Workbook

Sheet Assumptions & Scope
A1: Cosec Azure → AWS Migration — TCO Model
A2: Prepared by Minfy Technologies | AWS Premier Partner | Region: AWS Frankfurt (eu-central-1) Primary, AWS Ireland (eu-west-1) DR
A4: REGION & DR
A5: Primary region | B5: AWS Frankfurt (eu-central-1) — replaces current Azure North Europe (Dublin) production
A6: DR region | B6: AWS Ireland (eu-west-1) via AWS DRS — 64 Production-environment servers (excludes shared Dev/Test/Prod utility servers)
A8: MIGRATION STRATEGY
A9: Approach | B9: Lift-and-shift for all servers, EXCEPT SQL Server consolidation (see below)
A10: SQL Server consolidation | B10: 6 SQL Server VMs consolidated to 4 right-sized target instances, based on utilization data. Recommended for validation by the database administration team, as per-database IOPS and growth data were not available during sizing.
A11: Instance family | B11: AMD-based instance families throughout: m6a / r6a / c6a for general workloads, m7a for the new Active Directory Domain Controllers
A12: Additional AD Domain Controllers | B12: 2 new EC2 instances added for Active Directory, in addition to SCDPT01/SCDPT02 already in migration scope. Sized as m7a.2xlarge (8 vCPU / 32 GB).
A13: RHEL servers | B13: Treated as generic Linux; RHEL subscription is BYOL — no additional OS subscription cost modeled
A14: SQL Server licensing | B14: BYOL — no SQL Server license cost modeled
A16: PURCHASING MODEL
A17: Production + shared 'Prod/UAT/Dev' servers | B17: 3-Year No Upfront (CSP) — always-on, 730 hrs/month
A18: UAT + Dev servers | B18: On-Demand, 12 hours/day x 5 days/week = 260 hrs/month
A19: Support plan | B19: None modeled
A20: EDP / Credits | B20: None modeled
A22: SCOPE
A23: Source of scope | B23: Migration_Waves_v1.xlsx (authoritative, supersedes earlier working lists)
A24: In-scope servers | B24: 110 servers per the migration wave plan, consolidated to 108 compute instances (SQL Server consolidation) plus 2 new Active Directory Domain Controllers = 110 total compute instances
A25: Excluded from cost model | B25: Windows XP fleet (MAPAS x7 + pt5533vmXP-test + pt6202vm-test), NOTESMAIL01, SERVIMP, servimp10g-test, checkpoint firewall cluster, and other servers not present in Migration Waves file — not costed in this model
A26: Oracle-upgrade-dependent servers (14) | B26: Included in cost; sequenced as LAST migration wave in the roadmap (does not change 3-year cost total, only timing/phasing)
A28: BACKUP (AWS Backup)
A29: Production | B29: Daily backup, 30-day retention
A30: UAT | B30: Weekly backup, 1-month retention
A31: Dev | B31: Weekly backup, 1-month retention (aligned with UAT policy)
A33: NETWORK
A34: Transit Gateway | B34: 4 attachments, 100 GB/month data transfer each
A36: AZURE BASELINE
A37: Composition | B37: Azure infrastructure cost only. Managed Services (a separate vendor/IMS cost) is excluded, as it is not comparable to AWS infrastructure spend and would not be replaced 1:1 by the AWS migration.
A38: Known actuals | B38: December 2025 and January 2026 only (invoicing gap from February 2026 due to a tenant-to-branch transition)
A39: Remaining months (Feb-Dec 2026) | B39: Held flat at the average of the two known months. This is a modeling assumption, not actual billing data, and should be refreshed once further invoices are available.
A42: DATA QUALITY NOTES
A43: Memory utilization data | B43: Two source tabs (Final Report-06-04-26, COSEC_VM_Metrics) contained negative MemUsed values — an export artifact. The 'Final Report As per 21-04' tab was used instead as the authoritative, internally-consistent source.
A44: SSAGEPeople / SSAGESEI vCPU | B44: Not present in any discovery export. Inferred as 8 vCPU based on comparable Sage systems (D8s_v4 class, 32 GB RAM confirmed). Recommended for validation with the infrastructure team prior to final sign-off.
A46: PRICING DISCLAIMER
A47: AWS pricing used in this model | B47: EC2, storage, backup, DRS, network, and FX rates have been verified against the AWS Pricing Calculator and current CSP rate card (see Pricing Inputs tab, green-highlighted cells). Remaining modeling assumptions (DRS staging percentage, backup storage multipliers, hours-per-month) are methodology choices rather than market rates and remain open for review.
A49: RIGHT-SIZING METHODOLOGY
A50: Approach | B50: Moderate right-sizing applied to the 104 lift-and-shift instances (SQL consolidation and new AD DCs sized separately). Candidate instances include the original AMD family plus r6a.large as a lower-vCPU alternative where memory need is met at a lower vCPU count.
A51: CPU sizing | B51: Target vCPU = CEILING(Avg CPU% x current vCPU x 4), capped so it never exceeds the current lift-and-shift spec. Average CPU is sourced from the agent-based discovery export (current Azure environment), which reads consistently higher than the Azure Monitor platform metrics used earlier and is treated as the more conservative, and more current, basis.
...

Sheet Server Inventory
A1: Server Inventory & Monthly Cost Detail (110 instances)
A2: One row per target AWS instance. Compute/Storage/Backup/DRS costs computed via formula from Pricing Inputs tab.
A4: # | B4: VM Name / Target | C4: Environment | D4: Azure SKU (source) | E4: Azure vCPU | F4: Azure RAM (GB) | G4: OS Disk (GB) | H4: Data Disk (GB) | I4: Total Disk (GB) | J4: OS Type | K4: Target AWS Instance | L4: Purchase Model | M4: Monthly Hours | N4: Hourly Rate ($) | O4: Monthly Compute ($) | P4: Monthly Storage ($) | Q4: Monthly Backup ($) | R4: Monthly DRS ($) | S4: Total Monthly ($) | T4: Notes | U4: Right-Sized Instance (Moderate) | V4: Right-Sized vCPU | W4: Right-Sized RAM (GB) | X4: Right-Sizing Note | Y4: DRS Eligible (Prod only) | Z4: Utilization Data Source
A5: 1 | B5: DLCQRADAR | C5: Prod | D5: Standard_D2s_v3 | E5: 2 | F5: 8 | G5: 128 | H5: 256 | I5: =G5+H5 -> 384 | J5: Linux | K5: m6a.large | L5: 3-Yr No Upfront | M5: =IF(L5="3-Yr No Upfront",'Pricing Inputs'!$B$29,'Pricing Inputs'!$B$30) -> 730 | N5: =IF(U5="m7a.2xlarge",IF(L5="3-Yr No Upfront",'Pricing Inputs'!$E$18,'Pricing Inputs'!$D$18),IFERROR(INDEX('Pricing Inputs'!$D$6:$G$14,MATCH(U5,'Pricing Inputs'!$A$6:$A$14,0),IF(L5="3-Yr No Upfront",IF(J5="Windows",4,3),IF(J5="Windows",2,1))),"CHECK")) -> 0.05383 | O5: =M5*N5 -> 39.2959 | P5: =I5*'Pricing Inputs'!$B$22 -> 36.5568 | Q5: =I5*'Pricing Inputs'!$B$24*IF(OR(C5="Prod",C5="Prod/UAT/Dev"),'Pricing Inputs'!$B$31,'Pricing Inputs'!$B$32) -> 28.8 | R5: =IF(Y5="Yes",('Pricing Inputs'!$B$25*'Pricing Inputs'!$B$29)+(I5*'Pricing Inputs'!$B$26*'Pricing Inputs'!$B$23),0) -> 27.1984 | S5: =O5+P5+Q5+R5 -> 131.8511 | U5: m6a.large | V5: 2 | W5: 8 | X5: Moderate right-size (source: Excel (fallback - not present in zip export)): avg CPU 14.1% x4 buffer = 2 vCPU target; avg RAM used 3.3GB x1.75 buffer = 5.8GB target (capped at current spec). Cheapest fit chosen. Never exceeds current spec. | Y5: Yes | Z5: Excel (fallback - not present in zip export)
A6: 2 | B6: INTRANET | C6: Prod | D6: Standard_D4s_v4 | E6: 4 | F6: 16 | G6: 127 | H6: 32 | I6: =G6+H6 -> 159 | J6: Windows | K6: m6a.xlarge | L6: 3-Yr No Upfront | M6: =IF(L6="3-Yr No Upfront",'Pricing Inputs'!$B$29,'Pricing Inputs'!$B$30) -> 730 | N6: =IF(U6="m7a.2xlarge",IF(L6="3-Yr No Upfront",'Pricing Inputs'!$E$18,'Pricing Inputs'!$D$18),IFERROR(INDEX('Pricing Inputs'!$D$6:$G$14,MATCH(U6,'Pricing Inputs'!$A$6:$A$14,0),IF(L6="3-Yr No Upfront",IF(J6="Windows",4,3),IF(J6="Windows",2,1))),"CHECK")) -> 0.14583 | O6: =M6*N6 -> 106.4559 | P6: =I6*'Pricing Inputs'!$B$22 -> 15.1368 | Q6: =I6*'Pricing Inputs'!$B$24*IF(OR(C6="Prod",C6="Prod/UAT/Dev"),'Pricing Inputs'!$B$31,'Pricing Inputs'!$B$32) -> 11.925 | R6: =IF(Y6="Yes",('Pricing Inputs'!$B$25*'Pricing Inputs'!$B$29)+(I6*'Pricing Inputs'!$B$26*'Pricing Inputs'!$B$23),0) -> 23.2384 | S6: =O6+P6+Q6+R6 -> 156.7561 | U6: m6a.large | V6: 2 | W6: 8 | X6: Moderate right-size (source: zip (agent, current Azure environment)): avg CPU 8.1% x4 buffer = 2 vCPU target; avg RAM used 3.8GB x1.75 buffer = 6.6GB target (capped at current spec). Cheapest fit chosen. Never exceeds current spec. | Y6: Yes | Z6: zip (agent, current Azure environment)
A7: 3 | B7: PT-03-VM | C7: UAT | D7: Standard_D2s_v3 | E7: 2 | F7: 7.95 | G7: 256 | H7: 0 | I7: =G7+H7 -> 256 | J7: Windows | K7: m6a.large | L7: On-Demand 12x5 | M7: =IF(L7="3-Yr No Upfront",'Pricing Inputs'!$B$29,'Pricing Inputs'!$B$30) -> 260 | N7: =IF(U7="m7a.2xlarge",IF(L7="3-Yr No Upfront",'Pricing Inputs'!$E$18,'Pricing Inputs'!$D$18),IFERROR(INDEX('Pricing Inputs'!$D$6:$G$14,MATCH(U7,'Pricing Inputs'!$A$6:$A$14,0),IF(L7="3-Yr No Upfront",IF(J7="Windows",4,3),IF(J7="Windows",2,1))),"CHECK")) -> 0.1955 | O7: =M7*N7 -> 50.83 | P7: =I7*'Pricing Inputs'!$B$22 -> 24.3712 | Q7: =I7*'Pricing Inputs'!$B$24*IF(OR(C7="Prod",C7="Prod/UAT/Dev"),'Pricing Inputs'!$B$31,'Pricing Inputs'!$B$32) -> 15.36 | R7: =IF(Y7="Yes",('Pricing Inputs'!$B$25*'Pricing Inputs'!$B$29)+(I7*'Pricing Inputs'!$B$26*'Pricing Inputs'!$B$23),0) -> 0 | S7: =O7+P7+Q7+R7 -> 90.5612 | U7: m6a.large | V7: 2 | W7: 7.95 | X7: Moderate right-size (source: zip (agent, current Azure environment)): avg CPU 51.9% x4 buffer = 2 vCPU target; avg RAM used 5.1GB x1.75 buffer = 8.0GB target (capped at current spec). Cheapest fit chosen. Never exceeds current spec. | Y7: No | Z7: zip (agent, current Azure environment)
A8: 4 | B8: PT-04-VM | C8: UAT | D8: Standard_D2s_v3 | E8: 2 | F8: 7.95 | G8: 256 | H8: 0 | I8: =G8+H8 -> 256 | J8: Windows | K8: m6a.large | L8: On-Demand 12x5 | M8: =IF(L8="3-Yr No Upfront",'Pricing Inputs'!$B$29,'Pricing Inputs'!$B$30) -> 260 | N8: =IF(U8="m7a.2xlarge",IF(L8="3-Yr No Upfront",'Pricing Inputs'!$E$18,'Pricing Inputs'!$D$18),IFERROR(INDEX('Pricing Inputs'!$D$6:$G$14,MATCH(U8,'Pricing Inputs'!$A$6:$A$14,0),IF(L8="3-Yr No Upfront",IF(J8="Windows",4,3),IF(J8="Windows",2,1))),"CHECK")) -> 0.1955 | O8: =M8*N8 -> 50.83 | P8: =I8*'Pricing Inputs'!$B$22 -> 24.3712 | Q8: =I8*'Pricing Inputs'!$B$24*IF(OR(C8="Prod",C8="Prod/UAT/Dev"),'Pricing Inputs'!$B$31,'Pricing Inputs'!$B$32) -> 15.36 | R8: =IF(Y8="Yes",('Pricing Inputs'!$B$25*'Pricing Inputs'!$B$29)+(I8*'Pricing Inputs'!$B$26*'Pricing Inputs'!$B$23),0) -> 0 | S8: =O8+P8+Q8+R8 -> 90.5612 | U8: m6a.large | V8: 2 | W8: 7.95 | X8: Moderate right-size (source: zip (agent, current Azure environment)): avg CPU 70.8% x4 buffer = 2 vCPU target; avg RAM used 4.8GB x1.75 buffer = 8.0GB target (capped at current spec). Cheapest fit chosen. Never exceeds current spec. | Y8: No | Z8: zip (agent, current Azure environment)
A9: 5 | B9: PTADRISOFT01VM | C9: Prod/UAT/Dev | D9: Standard_B4s_v2 | E9: 4 | F9: 16 | G9: 256 | H9: 0 | I9: =G9+H9 -> 256 | J9: Windows | K9: m6a.xlarge | L9: 3-Yr No Upfront | M9: =IF(L9="3-Yr No Upfront",'Pricing Inputs'!$B$29,'Pricing Inputs'!$B$30) -> 730 | N9: =IF(U9="m7a.2xlarge",IF(L9="3-Yr No Upfront",'Pricing Inputs'!$E$18,'Pricing Inputs'!$D$18),IFERROR(INDEX('Pricing Inputs'!$D$6:$G$14,MATCH(U9,'Pricing Inputs'!$A$6:$A$14,0),IF(L9="3-Yr No Upfront",IF(J9="Windows",4,3),IF(J9="Windows",2,1))),"CHECK")) -> 0.29167 | O9: =M9*N9 -> 212.9191 | P9: =I9*'Pricing Inputs'!$B$22 -> 24.3712 | Q9: =I9*'Pricing Inputs'!$B$24*IF(OR(C9="Prod",C9="Prod/UAT/Dev"),'Pricing Inputs'!$B$31,'Pricing Inputs'!$B$32) -> 19.2 | R9: =IF(Y9="Yes",('Pricing Inputs'!$B$25*'Pricing Inputs'!$B$29)+(I9*'Pricing Inputs'!$B$26*'Pricing Inputs'!$B$23),0) -> 0 | S9: =O9+P9+Q9+R9 -> 256.4903 | U9: m6a.xlarge | V9: 4 | W9: 16 | X9: Moderate right-size (source: zip (agent, current Azure environment)): avg CPU 24.3% x4 buffer = 4 vCPU target; avg RAM used 12.0GB x1.75 buffer = 16.0GB target (capped at current spec). Cheapest fit chosen. Never exceeds current spec. | Y9: No | Z9: zip (agent, current Azure environment)
A10: 6 | B10: PTADRISOFT02VM | C10: Prod/UAT/Dev | D10: Standard_B4s_v2 | E10: 4 | F10: 16 | G10: 256 | H10: 0 | I10: =G10+H10 -> 256 | J10: Windows | K10: m6a.xlarge | L10: 3-Yr No Upfront | M10: =IF(L10="3-Yr No Upfront",'Pricing Inputs'!$B$29,'Pricing Inputs'!$B$30) -> 730 | N10: =IF(U10="m7a.2xlarge",IF(L10="3-Yr No Upfront",'Pricing Inputs'!$E$18,'Pricing Inputs'!$D$18),IFERROR(INDEX('Pricing Inputs'!$D$6:$G$14,MATCH(U10,'Pricing Inputs'!$A$6:$A$14,0),IF(L10="3-Yr No Upfront",IF(J10="Windows",4,3),IF(J10="Windows",2,1))),"CHECK")) -> 0.16336 | O10: =M10*N10 -> 119.2528 | P10: =I10*'Pricing Inputs'!$B$22 -> 24.3712 | Q10: =I10*'Pricing Inputs'!$B$24*IF(OR(C10="Prod",C10="Prod/UAT/Dev"),'Pricing Inputs'!$B$31,'Pricing Inputs'!$B$32) -> 19.2 | R10: =IF(Y10="Yes",('Pricing Inputs'!$B$25*'Pricing Inputs'!$B$29)+(I10*'Pricing Inputs'!$B$26*'Pricing Inputs'!$B$23),0) -> 0 | S10: =O10+P10+Q10+R10 -> 162.824 | U10: r6a.large | V10: 2 | W10: 16 | X10: Moderate right-size (source: zip (agent, current Azure environment)): avg CPU 11.8% x4 buffer = 2 vCPU target; avg RAM used 7.2GB x1.75 buffer = 12.6GB target (capped at current spec). Cheapest fit chosen. Never exceeds current spec. | Y10: No | Z10: zip (agent, current Azure environment)
A11: 7 | B11: PTADRISOFT03VM | C11: Prod/UAT/Dev | D11: Standard_B4s_v2 | E11: 4 | F11: 16 | G11: 256 | H11: 0 | I11: =G11+H11 -> 256 | J11: Windows | K11: m6a.xlarge | L11: 3-Yr No Upfront | M11: =IF(L11="3-Yr No Upfront",'Pricing Inputs'!$B$29,'Pricing Inputs'!$B$30) -> 730 | N11: =IF(U11="m7a.2xlarge",IF(L11="3-Yr No Upfront",'Pricing Inputs'!$E$18,'Pricing Inputs'!$D$18),IFERROR(INDEX('Pricing Inputs'!$D$6:$G$14,MATCH(U11,'Pricing Inputs'!$A$6:$A$14,0),IF(L11="3-Yr No Upfront",IF(J11="Windows",4,3),IF(J11="Windows",2,1))),"CHECK")) -> 0.16336 | O11: =M11*N11 -> 119.2528 | P11: =I11*'Pricing Inputs'!$B$22 -> 24.3712 | Q11: =I11*'Pricing Inputs'!$B$24*IF(OR(C11="Prod",C11="Prod/UAT/Dev"),'Pricing Inputs'!$B$31,'Pricing Inputs'!$B$32) -> 19.2 | R11: =IF(Y11="Yes",('Pricing Inputs'!$B$25*'Pricing Inputs'!$B$29)+(I11*'Pricing Inputs'!$B$26*'Pricing Inputs'!$B$23),0) -> 0 | S11: =O11+P11+Q11+R11 -> 162.824 | U11: r6a.large | V11: 2 | W11: 16 | X11: Moderate right-size (source: zip (agent, current Azure environment)): avg CPU 11.3% x4 buffer = 2 vCPU target; avg RAM used 7.9GB x1.75 buffer = 13.9GB target (capped at current spec). Cheapest fit chosen. Never exceeds current spec. | Y11: No | Z11: zip (agent, current Azure environment)
A12: 8 | B12: PTADRISOFT04VM | C12: Prod/UAT/Dev | D12: Standard_B4s_v2 | E12: 4 | F12: 16 | G12: 256 | H12: 0 | I12: =G12+H12 -> 256 | J12: Windows | K12: m6a.xlarge | L12: 3-Yr No Upfront | M12: =IF(L12="3-Yr No Upfront",'Pricing Inputs'!$B$29,'Pricing Inputs'!$B$30) -> 730 | N12: =IF(U12="m7a.2xlarge",IF(L12="3-Yr No Upfront",'Pricing Inputs'!$E$18,'Pricing Inputs'!$D$18),IFERROR(INDEX('Pricing Inputs'!$D$6:$G$14,MATCH(U12,'Pricing Inputs'!$A$6:$A$14,0),IF(L12="3-Yr No Upfront",IF(J12="Windows",4,3),IF(J12="Windows",2,1))),"CHECK")) -> 0.29167 | O12: =M12*N12 -> 212.9191 | P12: =I12*'Pricing Inputs'!$B$22 -> 24.3712 | Q12: =I12*'Pricing Inputs'!$B$24*IF(OR(C12="Prod",C12="Prod/UAT/Dev"),'Pricing Inputs'!$B$31,'Pricing Inputs'!$B$32) -> 19.2 | R12: =IF(Y12="Yes",('Pricing Inputs'!$B$25*'Pricing Inputs'!$B$29)+(I12*'Pricing Inputs'!$B$26*'Pricing Inputs'!$B$23),0) -> 0 | S12: =O12+P12+Q12+R12 -> 256.4903 | U12: m6a.xlarge | V12: 4 | W12: 16 | X12: Moderate right-size (source: zip (agent, current Azure environment)): avg CPU 20.9% x4 buffer = 4 vCPU target; avg RAM used 12.0GB x1.75 buffer = 16.0GB target (capped at current spec). Cheapest fit chosen. Never exceeds current spec. | Y12: No | Z12: zip (agent, current Azure environment)
A13: 9 | B13: PTADRISOFT05VM | C13: Prod/UAT/Dev | D13: Standard_B4s_v2 | E13: 4 | F13: 16 | G13: 256 | H13: 0 | I13: =G13+H13 -> 256 | J13: Windows | K13: m6a.xlarge | L13: 3-Yr No Upfront | M13: =IF(L13="3-Yr No Upfront",'Pricing Inputs'!$B$29,'Pricing Inputs'!$B$30) -> 730 | N13: =IF(U13="m7a.2xlarge",IF(L13="3-Yr No Upfront",'Pricing Inputs'!$E$18,'Pricing Inputs'!$D$18),IFERROR(INDEX('Pricing Inputs'!$D$6:$G$14,MATCH(U13,'Pricing Inputs'!$A$6:$A$14,0),IF(L13="3-Yr No Upfront",IF(J13="Windows",4,3),IF(J13="Windows",2,1))),"CHECK")) -> 0.16336 | O13: =M13*N13 -> 119.2528 | P13: =I13*'Pricing Inputs'!$B$22 -> 24.3712 | Q13: =I13*'Pricing Inputs'!$B$24*IF(OR(C13="Prod",C13="Prod/UAT/Dev"),'Pricing Inputs'!$B$31,'Pricing Inputs'!$B$32) -> 19.2 | R13: =IF(Y13="Yes",('Pricing Inputs'!$B$25*'Pricing Inputs'!$B$29)+(I13*'Pricing Inputs'!$B$26*'Pricing Inputs'!$B$23),0) -> 0 | S13: =O13+P13+Q13+R13 -> 162.824 | U13: r6a.large | V13: 2 | W13: 16 | X13: Moderate right-size (source: zip (agent, current Azure environment)): avg CPU 11.3% x4 buffer = 2 vCPU target; avg RAM used 6.3GB x1.75 buffer = 11.0GB target (capped at current spec). Cheapest fit chosen. Never exceeds current spec. | Y13: No | Z13: zip (agent, current Azure environment)
A14: 10 | B14: PTATOS03VM | C14: Prod/UAT/Dev | D14: Standard_D4s_v3 | E14: 4 | F14: 16 | G14: 256 | H14: 0 | I14: =G14+H14 -> 256 | J14: Windows | K14: m6a.xlarge | L14: 3-Yr No Upfront | M14: =IF(L14="3-Yr No Upfront",'Pricing Inputs'!$B$29,'Pricing Inputs'!$B$30) -> 730 | N14: =IF(U14="m7a.2xlarge",IF(L14="3-Yr No Upfront",'Pricing Inputs'!$E$18,'Pricing Inputs'!$D$18),IFERROR(INDEX('Pricing Inputs'!$D$6:$G$14,MATCH(U14,'Pricing Inputs'!$A$6:$A$14,0),IF(L14="3-Yr No Upfront",IF(J14="Windows",4,3),IF(J14="Windows",2,1))),"CHECK")) -> 0.29167 | O14: =M14*N14 -> 212.9191 | P14: =I14*'Pricing Inputs'!$B$22 -> 24.3712 | Q14: =I14*'Pricing Inputs'!$B$24*IF(OR(C14="Prod",C14="Prod/UAT/Dev"),'Pricing Inputs'!$B$31,'Pricing Inputs'!$B$32) -> 19.2 | R14: =IF(Y14="Yes",('Pricing Inputs'!$B$25*'Pricing Inputs'!$B$29)+(I14*'Pricing Inputs'!$B$26*'Pricing Inputs'!$B$23),0) -> 0 | S14: =O14+P14+Q14+R14 -> 256.4903 | U14: m6a.xlarge | V14: 4 | W14: 16 | X14: Moderate right-size (source: zip (agent, current Azure environment)): avg CPU 26.5% x4 buffer = 4 vCPU target; avg RAM used 5.5GB x1.75 buffer = 9.7GB target (capped at current spec). Cheapest fit chosen. Never exceeds current spec. | Y14: No | Z14: zip (agent, current Azure environment)
A15: 11 | B15: PTATOS05VM | C15: Prod/UAT/Dev | D15: Standard_D4s_v3 | E15: 4 | F15: 16 | G15: 256 | H15: 0 | I15: =G15+H15 -> 256 | J15: Windows | K15: m6a.xlarge | L15: 3-Yr No Upfront | M15: =IF(L15="3-Yr No Upfront",'Pricing Inputs'!$B$29,'Pricing Inputs'!$B$30) -> 730 | N15: =IF(U15="m7a.2xlarge",IF(L15="3-Yr No Upfront",'Pricing Inputs'!$E$18,'Pricing Inputs'!$D$18),IFERROR(INDEX('Pricing Inputs'!$D$6:$G$14,MATCH(U15,'Pricing Inputs'!$A$6:$A$14,0),IF(L15="3-Yr No Upfront",IF(J15="Windows",4,3),IF(J15="Windows",2,1))),"CHECK")) -> 0.29167 | O15: =M15*N15 -> 212.9191 | P15: =I15*'Pricing Inputs'!$B$22 -> 24.3712 | Q15: =I15*'Pricing Inputs'!$B$24*IF(OR(C15="Prod",C15="Prod/UAT/Dev"),'Pricing Inputs'!$B$31,'Pricing Inputs'!$B$32) -> 19.2 | R15: =IF(Y15="Yes",('Pricing Inputs'!$B$25*'Pricing Inputs'!$B$29)+(I15*'Pricing Inputs'!$B$26*'Pricing Inputs'!$B$23),0) -> 0 | S15: =O15+P15+Q15+R15 -> 256.4903 | U15: m6a.xlarge | V15: 4 | W15: 16 | X15: Moderate right-size (source: zip (agent, current Azure environment)): avg CPU 40.9% x4 buffer = 4 vCPU target; avg RAM used 7.0GB x1.75 buffer = 12.3GB target (capped at current spec). Cheapest fit chosen. Never exceeds current spec. | Y15: No | Z15: zip (agent, current Azure environment)
A16: 12 | B16: PTATOS07VM | C16: Prod/UAT/Dev | D16: Standard_D4s_v3 | E16: 4 | F16: 16 | G16: 256 | H16: 0 | I16: =G16+H16 -> 256 | J16: Windows | K16: m6a.xlarge | L16: 3-Yr No Upfront | M16: =IF(L16="3-Yr No Upfront",'Pricing Inputs'!$B$29,'Pricing Inputs'!$B$30) -> 730 | N16: =IF(U16="m7a.2xlarge",IF(L16="3-Yr No Upfront",'Pricing Inputs'!$E$18,'Pricing Inputs'!$D$18),IFERROR(INDEX('Pricing Inputs'!$D$6:$G$14,MATCH(U16,'Pricing Inputs'!$A$6:$A$14,0),IF(L16="3-Yr No Upfront",IF(J16="Windows",4,3),IF(J16="Windows",2,1))),"CHECK")) -> 0.29167 | O16: =M16*N16 -> 212.9191 | P16: =I16*'Pricing Inputs'!$B$22 -> 24.3712 | Q16: =I16*'Pricing Inputs'!$B$24*IF(OR(C16="Prod",C16="Prod/UAT/Dev"),'Pricing Inputs'!$B$31,'Pricing Inputs'!$B$32) -> 19.2 | R16: =IF(Y16="Yes",('Pricing Inputs'!$B$25*'Pricing Inputs'!$B$29)+(I16*'Pricing Inputs'!$B$26*'Pricing Inputs'!$B$23),0) -> 0 | S16: =O16+P16+Q16+R16 -> 256.4903 | U16: m6a.xlarge | V16: 4 | W16: 16 | X16: Moderate right-size (source: zip (agent, current Azure environment)): avg CPU 35.0% x4 buffer = 4 vCPU target; avg RAM used 6.7GB x1.75 buffer = 11.7GB target (capped at current spec). Cheapest fit chosen. Never exceeds current spec. | Y16: No | Z16: zip (agent, current Azure environment)
... A83: 79 | B83: SRHUsrPrm1-Prod | C83: Prod | D83: Standard_D4s_v5 | E83: 4 | F83: 16 | G83: 127 | H83: 256 | I83: =G83+H83 -> 383 | J83: Windows | K83: m6a.xlarge | L83: 3-Yr No Upfront | M83: =IF(L83="3-Yr No Upfront",'Pricing Inputs'!$B$29,'Pricing Inputs'!$B$30) -> 730 | N83: =IF(U83="m7a.2xlarge",IF(L83="3-Yr No Upfront",'Pricing Inputs'!$E$18,'Pricing Inputs'!$D$18),IFERROR(INDEX('Pricing Inputs'!$D$6:$G$14,MATCH(U83,'Pricing Inputs'!$A$6:$A$14,0),IF(L83="3-Yr No Upfront",IF(J83="Windows",4,3),IF(J83="Windows",2,1))),"CHECK")) -> 0.16336 | O83: =M83*N83 -> 119.2528 | P83: =I83*'Pricing Inputs'!$B$22 -> 36.4616 | Q83: =I83*'Pricing Inputs'!$B$24*IF(OR(C83="Prod",C83="Prod/UAT/Dev"),'Pricing Inputs'!$B$31,'Pricing Inputs'!$B$32) -> 28.725 | R83: =IF(Y83="Yes",('Pricing Inputs'!$B$25*'Pricing Inputs'!$B$29)+(I83*'Pricing Inputs'!$B$26*'Pricing Inputs'!$B$23),0) -> 27.1808 | S83: =O83+P83+Q83+R83 -> 211.6202 | U83: r6a.large | V83: 2 | W83: 16 | X83: Moderate right-size (source: zip (agent, current Azure environment)): avg CPU 8.7% x4 buffer = 2 vCPU target; avg RAM used 5.2GB x1.75 buffer = 9.0GB target (capped at current spec). Cheapest fit chosen. Never exceeds current spec. | Y83: Yes | Z83: zip (agent, current Azure environment)
A84: 80 | B84: SSAGEPeople | C84: Prod | E84: 8 | F84: 32 | G84: 0 | H84: 0 | I84: =G84+H84 -> 0 | J84: Windows | K84: m6a.2xlarge | L84: 3-Yr No Upfront | M84: =IF(L84="3-Yr No Upfront",'Pricing Inputs'!$B$29,'Pricing Inputs'!$B$30) -> 730 | N84: =IF(U84="m7a.2xlarge",IF(L84="3-Yr No Upfront",'Pricing Inputs'!$E$18,'Pricing Inputs'!$D$18),IFERROR(INDEX('Pricing Inputs'!$D$6:$G$14,MATCH(U84,'Pricing Inputs'!$A$6:$A$14,0),IF(L84="3-Yr No Upfront",IF(J84="Windows",4,3),IF(J84="Windows",2,1))),"CHECK")) -> 0.58333 | O84: =M84*N84 -> 425.8309 | P84: =I84*'Pricing Inputs'!$B$22 -> 0 | Q84: =I84*'Pricing Inputs'!$B$24*IF(OR(C84="Prod",C84="Prod/UAT/Dev"),'Pricing Inputs'!$B$31,'Pricing Inputs'!$B$32) -> 0 | R84: =IF(Y84="Yes",('Pricing Inputs'!$B$25*'Pricing Inputs'!$B$29)+(I84*'Pricing Inputs'!$B$26*'Pricing Inputs'!$B$23),0) -> 20.44 | S84: =O84+P84+Q84+R84 -> 446.2709 | T84: vCPU not available in source discovery data. Inferred as 8 vCPU based on comparable Sage systems (D8s_v4 class, 32 GB RAM confirmed). Recommended for validation with the infrastructure team. | U84: m6a.2xlarge | V84: 8 | W84: 32 | X84: Moderate right-size (source: zip (agent, current Azure environment)): avg CPU 11.1% x4 buffer = 4 vCPU target; avg RAM used 9.8GB x1.75 buffer = 17.2GB target (capped at current spec). Cheapest fit chosen. Never exceeds current spec. | Y84: Yes | Z84: zip (agent, current Azure environment)
A85: 81 | B85: SSAGESEI | C85: Prod | E85: 8 | F85: 32 | G85: 0 | H85: 0 | I85: =G85+H85 -> 0 | J85: Windows | K85: m6a.2xlarge | L85: 3-Yr No Upfront | M85: =IF(L85="3-Yr No Upfront",'Pricing Inputs'!$B$29,'Pricing Inputs'!$B$30) -> 730 | N85: =IF(U85="m7a.2xlarge",IF(L85="3-Yr No Upfront",'Pricing Inputs'!$E$18,'Pricing Inputs'!$D$18),IFERROR(INDEX('Pricing Inputs'!$D$6:$G$14,MATCH(U85,'Pricing Inputs'!$A$6:$A$14,0),IF(L85="3-Yr No Upfront",IF(J85="Windows",4,3),IF(J85="Windows",2,1))),"CHECK")) -> 0.58333 | O85: =M85*N85 -> 425.8309 | P85: =I85*'Pricing Inputs'!$B$22 -> 0 | Q85: =I85*'Pricing Inputs'!$B$24*IF(OR(C85="Prod",C85="Prod/UAT/Dev"),'Pricing Inputs'!$B$31,'Pricing Inputs'!$B$32) -> 0 | R85: =IF(Y85="Yes",('Pricing Inputs'!$B$25*'Pricing Inputs'!$B$29)+(I85*'Pricing Inputs'!$B$26*'Pricing Inputs'!$B$23),0) -> 20.44 | S85: =O85+P85+Q85+R85 -> 446.2709 | T85: vCPU not available in source discovery data. Inferred as 8 vCPU based on comparable Sage systems (D8s_v4 class, 32 GB RAM confirmed). Recommended for validation with the infrastructure team. | U85: m6a.2xlarge | V85: 8 | W85: 32 | X85: Moderate right-size (source: zip (agent, current Azure environment)): avg CPU 21.4% x4 buffer = 7 vCPU target; avg RAM used 6.2GB x1.75 buffer = 10.9GB target (capped at current spec). Cheapest fit chosen. Never exceeds current spec. | Y85: Yes | Z85: zip (agent, current Azure environment)
A86: 82 | B86: SSAGEX3-Prod | C86: Prod | D86: Standard_D8s_v4 | E86: 8 | F86: 32 | G86: 127 | H86: 576 | I86: =G86+H86 -> 703 | J86: Windows | K86: m6a.2xlarge | L86: 3-Yr No Upfront | M86: =IF(L86="3-Yr No Upfront",'Pricing Inputs'!$B$29,'Pricing Inputs'!$B$30) -> 730 | N86: =IF(U86="m7a.2xlarge",IF(L86="3-Yr No Upfront",'Pricing Inputs'!$E$18,'Pricing Inputs'!$D$18),IFERROR(INDEX('Pricing Inputs'!$D$6:$G$14,MATCH(U86,'Pricing Inputs'!$A$6:$A$14,0),IF(L86="3-Yr No Upfront",IF(J86="Windows",4,3),IF(J86="Windows",2,1))),"CHECK")) -> 0.58333 | O86: =M86*N86 -> 425.8309 | P86: =I86*'Pricing Inputs'!$B$22 -> 66.9256 | Q86: =I86*'Pricing Inputs'!$B$24*IF(OR(C86="Prod",C86="Prod/UAT/Dev"),'Pricing Inputs'!$B$31,'Pricing Inputs'!$B$32) -> 52.725 | R86: =IF(Y86="Yes",('Pricing Inputs'!$B$25*'Pricing Inputs'!$B$29)+(I86*'Pricing Inputs'!$B$26*'Pricing Inputs'!$B$23),0) -> 32.8128 | S86: =O86+P86+Q86+R86 -> 578.2943 | U86: m6a.2xlarge | V86: 8 | W86: 32 | X86: Moderate right-size (source: zip (agent, current Azure environment)): avg CPU 20.9% x4 buffer = 7 vCPU target; avg RAM used 23.8GB x1.75 buffer = 32.0GB target (capped at current spec). Cheapest fit chosen. Never exceeds current spec. | Y86: Yes | Z86: zip (agent, current Azure environment)
A87: 83 | B87: SSAGEX3-TST | C87: UAT | D87: Standard_D8s_v4 | E87: 8 | F87: 32 | G87: 512 | H87: 320 | I87: =G87+H87 -> 832 | J87: Windows | K87: m6a.2xlarge | L87: On-Demand 12x5 | M87: =IF(L87="3-Yr No Upfront",'Pricing Inputs'!$B$29,'Pricing Inputs'!$B$30) -> 260 | N87: =IF(U87="m7a.2xlarge",IF(L87="3-Yr No Upfront",'Pricing Inputs'!$E$18,'Pricing Inputs'!$D$18),IFERROR(INDEX('Pricing Inputs'!$D$6:$G$14,MATCH(U87,'Pricing Inputs'!$A$6:$A$14,0),IF(L87="3-Yr No Upfront",IF(J87="Windows",4,3),IF(J87="Windows",2,1))),"CHECK")) -> 0.391 | O87: =M87*N87 -> 101.66 | P87: =I87*'Pricing Inputs'!$B$22 -> 79.2064 | Q87: =I87*'Pricing Inputs'!$B$24*IF(OR(C87="Prod",C87="Prod/UAT/Dev"),'Pricing Inputs'!$B$31,'Pricing Inputs'!$B$32) -> 49.92 | R87: =IF(Y87="Yes",('Pricing Inputs'!$B$25*'Pricing Inputs'!$B$29)+(I87*'Pricing Inputs'!$B$26*'Pricing Inputs'!$B$23),0) -> 0 | S87: =O87+P87+Q87+R87 -> 230.7864 | U87: m6a.xlarge | V87: 4 | W87: 16 | X87: Moderate right-size (source: zip (agent, current Azure environment)): avg CPU 6.4% x4 buffer = 3 vCPU target; avg RAM used 7.3GB x1.75 buffer = 12.8GB target (capped at current spec). Cheapest fit chosen. Never exceeds current spec. | Y87: No | Z87: zip (agent, current Azure environment)
A88: 84 | B88: SSIID-Prod | C88: Prod | D88: Standard_D8as_v5 | E88: 8 | F88: 32 | G88: 127 | H88: 512 | I88: =G88+H88 -> 639 | J88: Windows | K88: m6a.2xlarge | L88: 3-Yr No Upfront | M88: =IF(L88="3-Yr No Upfront",'Pricing Inputs'!$B$29,'Pricing Inputs'!$B$30) -> 730 | N88: =IF(U88="m7a.2xlarge",IF(L88="3-Yr No Upfront",'Pricing Inputs'!$E$18,'Pricing Inputs'!$D$18),IFERROR(INDEX('Pricing Inputs'!$D$6:$G$14,MATCH(U88,'Pricing Inputs'!$A$6:$A$14,0),IF(L88="3-Yr No Upfront",IF(J88="Windows",4,3),IF(J88="Windows",2,1))),"CHECK")) -> 0.58333 | O88: =M88*N88 -> 425.8309 | P88: =I88*'Pricing Inputs'!$B$22 -> 60.8328 | Q88: =I88*'Pricing Inputs'!$B$24*IF(OR(C88="Prod",C88="Prod/UAT/Dev"),'Pricing Inputs'!$B$31,'Pricing Inputs'!$B$32) -> 47.925 | R88: =IF(Y88="Yes",('Pricing Inputs'!$B$25*'Pricing Inputs'!$B$29)+(I88*'Pricing Inputs'!$B$26*'Pricing Inputs'!$B$23),0) -> 31.6864 | S88: =O88+P88+Q88+R88 -> 566.2751 | U88: m6a.2xlarge | V88: 8 | W88: 32 | X88: Moderate right-size (source: zip (agent, current Azure environment)): avg CPU 12.4% x4 buffer = 4 vCPU target; avg RAM used 17.4GB x1.75 buffer = 30.5GB target (capped at current spec). Cheapest fit chosen. Never exceeds current spec. | Y88: Yes | Z88: zip (agent, current Azure environment)
A89: 85 | B89: SSIIDT | C89: UAT | D89: Standard_D4s_v4 | E89: 4 | F89: 16 | G89: 127 | H89: 512 | I89: =G89+H89 -> 639 | J89: Windows | K89: m6a.xlarge | L89: On-Demand 12x5 | M89: =IF(L89="3-Yr No Upfront",'Pricing Inputs'!$B$29,'Pricing Inputs'!$B$30) -> 260 | N89: =IF(U89="m7a.2xlarge",IF(L89="3-Yr No Upfront",'Pricing Inputs'!$E$18,'Pricing Inputs'!$D$18),IFERROR(INDEX('Pricing Inputs'!$D$6:$G$14,MATCH(U89,'Pricing Inputs'!$A$6:$A$14,0),IF(L89="3-Yr No Upfront",IF(J89="Windows",4,3),IF(J89="Windows",2,1))),"CHECK")) -> 0.391 | O89: =M89*N89 -> 101.66 | P89: =I89*'Pricing Inputs'!$B$22 -> 60.8328 | Q89: =I89*'Pricing Inputs'!$B$24*IF(OR(C89="Prod",C89="Prod/UAT/Dev"),'Pricing Inputs'!$B$31,'Pricing Inputs'!$B$32) -> 38.34 | R89: =IF(Y89="Yes",('Pricing Inputs'!$B$25*'Pricing Inputs'!$B$29)+(I89*'Pricing Inputs'!$B$26*'Pricing Inputs'!$B$23),0) -> 0 | S89: =O89+P89+Q89+R89 -> 200.8328 | U89: m6a.xlarge | V89: 4 | W89: 16 | X89: Moderate right-size (source: zip (agent, current Azure environment)): avg CPU 27.1% x4 buffer = 4 vCPU target; avg RAM used 12.2GB x1.75 buffer = 16.0GB target (capped at current spec). Cheapest fit chosen. Never exceeds current spec. | Y89: No | Z89: zip (agent, current Azure environment)
A90: 86 | B90: SWEBLOGT | C90: Dev | D90: Standard_D4s_v4 | E90: 4 | F90: 16 | G90: 100 | H90: 75 | I90: =G90+H90 -> 175 | J90: Windows | K90: m6a.xlarge | L90: On-Demand 12x5 | M90: =IF(L90="3-Yr No Upfront",'Pricing Inputs'!$B$29,'Pricing Inputs'!$B$30) -> 260 | N90: =IF(U90="m7a.2xlarge",IF(L90="3-Yr No Upfront",'Pricing Inputs'!$E$18,'Pricing Inputs'!$D$18),IFERROR(INDEX('Pricing Inputs'!$D$6:$G$14,MATCH(U90,'Pricing Inputs'!$A$6:$A$14,0),IF(L90="3-Yr No Upfront",IF(J90="Windows",4,3),IF(J90="Windows",2,1))),"CHECK")) -> 0.391 | O90: =M90*N90 -> 101.66 | P90: =I90*'Pricing Inputs'!$B$22 -> 16.66 | Q90: =I90*'Pricing Inputs'!$B$24*IF(OR(C90="Prod",C90="Prod/UAT/Dev"),'Pricing Inputs'!$B$31,'Pricing Inputs'!$B$32) -> 10.5 | R90: =IF(Y90="Yes",('Pricing Inputs'!$B$25*'Pricing Inputs'!$B$29)+(I90*'Pricing Inputs'!$B$26*'Pricing Inputs'!$B$23),0) -> 0 | S90: =O90+P90+Q90+R90 -> 128.82 | U90: m6a.xlarge | V90: 4 | W90: 16 | X90: Moderate right-size (source: zip (agent, current Azure environment)): avg CPU 31.9% x4 buffer = 4 vCPU target; avg RAM used 10.1GB x1.75 buffer = 16.0GB target (capped at current spec). Cheapest fit chosen. Never exceeds current spec. | Y90: No | Z90: zip (agent, current Azure environment)
A91: 87 | B91: SWEBLOGT2 | C91: UAT | D91: Standard_D4s_v4 | E91: 4 | F91: 16 | G91: 127 | H91: 128 | I91: =G91+H91 -> 255 | J91: Windows | K91: m6a.xlarge | L91: On-Demand 12x5 | M91: =IF(L91="3-Yr No Upfront",'Pricing Inputs'!$B$29,'Pricing Inputs'!$B$30) -> 260 | N91: =IF(U91="m7a.2xlarge",IF(L91="3-Yr No Upfront",'Pricing Inputs'!$E$18,'Pricing Inputs'!$D$18),IFERROR(INDEX('Pricing Inputs'!$D$6:$G$14,MATCH(U91,'Pricing Inputs'!$A$6:$A$14,0),IF(L91="3-Yr No Upfront",IF(J91="Windows",4,3),IF(J91="Windows",2,1))),"CHECK")) -> 0.391 | O91: =M91*N91 -> 101.66 | P91: =I91*'Pricing Inputs'!$B$22 -> 24.276 | Q91: =I91*'Pricing Inputs'!$B$24*IF(OR(C91="Prod",C91="Prod/UAT/Dev"),'Pricing Inputs'!$B$31,'Pricing Inputs'!$B$32) -> 15.3 | R91: =IF(Y91="Yes",('Pricing Inputs'!$B$25*'Pricing Inputs'!$B$29)+(I91*'Pricing Inputs'!$B$26*'Pricing Inputs'!$B$23),0) -> 0 | S91: =O91+P91+Q91+R91 -> 141.236 | U91: m6a.xlarge | V91: 4 | W91: 16 | X91: Moderate right-size (source: zip (agent, current Azure environment)): avg CPU 23.1% x4 buffer = 4 vCPU target; avg RAM used 9.6GB x1.75 buffer = 16.0GB target (capped at current spec). Cheapest fit chosen. Never exceeds current spec. | Y91: No | Z91: zip (agent, current Azure environment)
A92: 88 | B92: SWLGador01-Prod | C92: Prod | D92: Standard_D4s_v4 | E92: 4 | F92: 16 | G92: 127 | H92: 128 | I92: =G92+H92 -> 255 | J92: Windows | K92: m6a.xlarge | L92: 3-Yr No Upfront | M92: =IF(L92="3-Yr No Upfront",'Pricing Inputs'!$B$29,'Pricing Inputs'!$B$30) -> 730 | N92: =IF(U92="m7a.2xlarge",IF(L92="3-Yr No Upfront",'Pricing Inputs'!$E$18,'Pricing Inputs'!$D$18),IFERROR(INDEX('Pricing Inputs'!$D$6:$G$14,MATCH(U92,'Pricing Inputs'!$A$6:$A$14,0),IF(L92="3-Yr No Upfront",IF(J92="Windows",4,3),IF(J92="Windows",2,1))),"CHECK")) -> 0.29167 | O92: =M92*N92 -> 212.9191 | P92: =I92*'Pricing Inputs'!$B$22 -> 24.276 | Q92: =I92*'Pricing Inputs'!$B$24*IF(OR(C92="Prod",C92="Prod/UAT/Dev"),'Pricing Inputs'!$B$31,'Pricing Inputs'!$B$32) -> 19.125 | R92: =IF(Y92="Yes",('Pricing Inputs'!$B$25*'Pricing Inputs'!$B$29)+(I92*'Pricing Inputs'!$B$26*'Pricing Inputs'!$B$23),0) -> 24.928 | S92: =O92+P92+Q92+R92 -> 281.2481 | U92: m6a.xlarge | V92: 4 | W92: 16 | X92: Moderate right-size (source: zip (agent, current Azure environment)): avg CPU 28.3% x4 buffer = 4 vCPU target; avg RAM used 9.5GB x1.75 buffer = 16.0GB target (capped at current spec). Cheapest fit chosen. Never exceeds current spec. | Y92: Yes | Z92: zip (agent, current Azure environment)
A93: 89 | B93: SWLGador02-Prod | C93: Prod | D93: Standard_D4s_v4 | E93: 4 | F93: 16 | G93: 127 | H93: 128 | I93: =G93+H93 -> 255 | J93: Windows | K93: m6a.xlarge | L93: 3-Yr No Upfront | M93: =IF(L93="3-Yr No Upfront",'Pricing Inputs'!$B$29,'Pricing Inputs'!$B$30) -> 730 | N93: =IF(U93="m7a.2xlarge",IF(L93="3-Yr No Upfront",'Pricing Inputs'!$E$18,'Pricing Inputs'!$D$18),IFERROR(INDEX('Pricing Inputs'!$D$6:$G$14,MATCH(U93,'Pricing Inputs'!$A$6:$A$14,0),IF(L93="3-Yr No Upfront",IF(J93="Windows",4,3),IF(J93="Windows",2,1))),"CHECK")) -> 0.29167 | O93: =M93*N93 -> 212.9191 | P93: =I93*'Pricing Inputs'!$B$22 -> 24.276 | Q93: =I93*'Pricing Inputs'!$B$24*IF(OR(C93="Prod",C93="Prod/UAT/Dev"),'Pricing Inputs'!$B$31,'Pricing Inputs'!$B$32) -> 19.125 | R93: =IF(Y93="Yes",('Pricing Inputs'!$B$25*'Pricing Inputs'!$B$29)+(I93*'Pricing Inputs'!$B$26*'Pricing Inputs'!$B$23),0) -> 24.928 | S93: =O93+P93+Q93+R93 -> 281.2481 | U93: m6a.xlarge | V93: 4 | W93: 16 | X93: Moderate right-size (source: zip (agent, current Azure environment)): avg CPU 25.7% x4 buffer = 4 vCPU target; avg RAM used 9.2GB x1.75 buffer = 16.0GB target (capped at current spec). Cheapest fit chosen. Never exceeds current spec. | Y93: Yes | Z93: zip (agent, current Azure environment)
A94: 90 | B94: SWLGador03-Prod | C94: Prod | D94: Standard_D8ls_v5 | E94: 8 | F94: 16 | G94: 127 | H94: 256 | I94: =G94+H94 -> 383 | J94: Windows | K94: c6a.2xlarge | L94: 3-Yr No Upfront | M94: =IF(L94="3-Yr No Upfront",'Pricing Inputs'!$B$29,'Pricing Inputs'!$B$30) -> 730 | N94: =IF(U94="m7a.2xlarge",IF(L94="3-Yr No Upfront",'Pricing Inputs'!$E$18,'Pricing Inputs'!$D$18),IFERROR(INDEX('Pricing Inputs'!$D$6:$G$14,MATCH(U94,'Pricing Inputs'!$A$6:$A$14,0),IF(L94="3-Yr No Upfront",IF(J94="Windows",4,3),IF(J94="Windows",2,1))),"CHECK")) -> 0.54918 | O94: =M94*N94 -> 400.9014 | P94: =I94*'Pricing Inputs'!$B$22 -> 36.4616 | Q94: =I94*'Pricing Inputs'!$B$24*IF(OR(C94="Prod",C94="Prod/UAT/Dev"),'Pricing Inputs'!$B$31,'Pricing Inputs'!$B$32) -> 28.725 | R94: =IF(Y94="Yes",('Pricing Inputs'!$B$25*'Pricing Inputs'!$B$29)+(I94*'Pricing Inputs'!$B$26*'Pricing Inputs'!$B$23),0) -> 27.1808 | S94: =O94+P94+Q94+R94 -> 493.2688 | U94: c6a.2xlarge | V94: 8 | W94: 16 | X94: Moderate right-size (source: zip (agent, current Azure environment)): avg CPU 12.4% x4 buffer = 4 vCPU target; avg RAM used 11.6GB x1.75 buffer = 16.0GB target (capped at current spec). Cheapest fit chosen. Never exceeds current spec. | Y94: Yes | Z94: zip (agent, current Azure environment)
A95: 91 | B95: SWinDoc01-Prod | C95: Prod | D95: Standard_D4s_v5 | E95: 4 | F95: 16 | G95: 127 | H95: 0 | I95: =G95+H95 -> 127 | J95: Windows | K95: m6a.xlarge | L95: 3-Yr No Upfront | M95: =IF(L95="3-Yr No Upfront",'Pricing Inputs'!$B$29,'Pricing Inputs'!$B$30) -> 730 | N95: =IF(U95="m7a.2xlarge",IF(L95="3-Yr No Upfront",'Pricing Inputs'!$E$18,'Pricing Inputs'!$D$18),IFERROR(INDEX('Pricing Inputs'!$D$6:$G$14,MATCH(U95,'Pricing Inputs'!$A$6:$A$14,0),IF(L95="3-Yr No Upfront",IF(J95="Windows",4,3),IF(J95="Windows",2,1))),"CHECK")) -> 0.14583 | O95: =M95*N95 -> 106.4559 | P95: =I95*'Pricing Inputs'!$B$22 -> 12.0904 | Q95: =I95*'Pricing Inputs'!$B$24*IF(OR(C95="Prod",C95="Prod/UAT/Dev"),'Pricing Inputs'!$B$31,'Pricing Inputs'!$B$32) -> 9.525 | R95: =IF(Y95="Yes",('Pricing Inputs'!$B$25*'Pricing Inputs'!$B$29)+(I95*'Pricing Inputs'!$B$26*'Pricing Inputs'!$B$23),0) -> 22.6752 | S95: =O95+P95+Q95+R95 -> 150.7465 | U95: m6a.large | V95: 2 | W95: 8 | X95: Moderate right-size (source: zip (agent, current Azure environment)): avg CPU 7.6% x4 buffer = 2 vCPU target; avg RAM used 4.5GB x1.75 buffer = 7.9GB target (capped at current spec). Cheapest fit chosen. Never exceeds current spec. | Y95: Yes | Z95: zip (agent, current Azure environment)
A96: 92 | B96: UIPROBOTDEV04 | C96: Dev | D96: Standard_D4s_v4 | E96: 4 | F96: 16 | G96: 256 | H96: 0 | I96: =G96+H96 -> 256 | J96: Windows | K96: m6a.xlarge | L96: On-Demand 12x5 | M96: =IF(L96="3-Yr No Upfront",'Pricing Inputs'!$B$29,'Pricing Inputs'!$B$30) -> 260 | N96: =IF(U96="m7a.2xlarge",IF(L96="3-Yr No Upfront",'Pricing Inputs'!$E$18,'Pricing Inputs'!$D$18),IFERROR(INDEX('Pricing Inputs'!$D$6:$G$14,MATCH(U96,'Pricing Inputs'!$A$6:$A$14,0),IF(L96="3-Yr No Upfront",IF(J96="Windows",4,3),IF(J96="Windows",2,1))),"CHECK")) -> 0.391 | O96: =M96*N96 -> 101.66 | P96: =I96*'Pricing Inputs'!$B$22 -> 24.3712 | Q96: =I96*'Pricing Inputs'!$B$24*IF(OR(C96="Prod",C96="Prod/UAT/Dev"),'Pricing Inputs'!$B$31,'Pricing Inputs'!$B$32) -> 15.36 | R96: =IF(Y96="Yes",('Pricing Inputs'!$B$25*'Pricing Inputs'!$B$29)+(I96*'Pricing Inputs'!$B$26*'Pricing Inputs'!$B$23),0) -> 0 | S96: =O96+P96+Q96+R96 -> 141.3912 | U96: m6a.xlarge | V96: 4 | W96: 16 | X96: Moderate right-size (source: zip (agent, current Azure environment)): avg CPU 18.1% x4 buffer = 3 vCPU target; avg RAM used 8.4GB x1.75 buffer = 14.8GB target (capped at current spec). Cheapest fit chosen. Never exceeds current spec. | Y96: No | Z96: zip (agent, current Azure environment)
A97: 93 | B97: UIPROBOTDEV05 | C97: Dev | D97: Standard_D4s_v4 | E97: 4 | F97: 16 | G97: 256 | H97: 0 | I97: =G97+H97 -> 256 | J97: Windows | K97: m6a.xlarge | L97: On-Demand 12x5 | M97: =IF(L97="3-Yr No Upfront",'Pricing Inputs'!$B$29,'Pricing Inputs'!$B$30) -> 260 | N97: =IF(U97="m7a.2xlarge",IF(L97="3-Yr No Upfront",'Pricing Inputs'!$E$18,'Pricing Inputs'!$D$18),IFERROR(INDEX('Pricing Inputs'!$D$6:$G$14,MATCH(U97,'Pricing Inputs'!$A$6:$A$14,0),IF(L97="3-Yr No Upfront",IF(J97="Windows",4,3),IF(J97="Windows",2,1))),"CHECK")) -> 0.391 | O97: =M97*N97 -> 101.66 | P97: =I97*'Pricing Inputs'!$B$22 -> 24.3712 | Q97: =I97*'Pricing Inputs'!$B$24*IF(OR(C97="Prod",C97="Prod/UAT/Dev"),'Pricing Inputs'!$B$31,'Pricing Inputs'!$B$32) -> 15.36 | R97: =IF(Y97="Yes",('Pricing Inputs'!$B$25*'Pricing Inputs'!$B$29)+(I97*'Pricing Inputs'!$B$26*'Pricing Inputs'!$B$23),0) -> 0 | S97: =O97+P97+Q97+R97 -> 141.3912 | U97: m6a.xlarge | V97: 4 | W97: 16 | X97: Moderate right-size (source: zip (agent, current Azure environment)): avg CPU 15.6% x4 buffer = 3 vCPU target; avg RAM used 8.2GB x1.75 buffer = 14.4GB target (capped at current spec). Cheapest fit chosen. Never exceeds current spec. | Y97: No | Z97: zip (agent, current Azure environment)
... A108: 104 | B108: swindoc01-test | C108: UAT | D108: Standard_D4s_v5 | E108: 4 | F108: 16 | G108: 127 | H108: 128 | I108: =G108+H108 -> 255 | J108: Windows | K108: m6a.xlarge | L108: On-Demand 12x5 | M108: =IF(L108="3-Yr No Upfront",'Pricing Inputs'!$B$29,'Pricing Inputs'!$B$30) -> 260 | N108: =IF(U108="m7a.2xlarge",IF(L108="3-Yr No Upfront",'Pricing Inputs'!$E$18,'Pricing Inputs'!$D$18),IFERROR(INDEX('Pricing Inputs'!$D$6:$G$14,MATCH(U108,'Pricing Inputs'!$A$6:$A$14,0),IF(L108="3-Yr No Upfront",IF(J108="Windows",4,3),IF(J108="Windows",2,1))),"CHECK")) -> 0.1955 | O108: =M108*N108 -> 50.83 | P108: =I108*'Pricing Inputs'!$B$22 -> 24.276 | Q108: =I108*'Pricing Inputs'!$B$24*IF(OR(C108="Prod",C108="Prod/UAT/Dev"),'Pricing Inputs'!$B$31,'Pricing Inputs'!$B$32) -> 15.3 | R108: =IF(Y108="Yes",('Pricing Inputs'!$B$25*'Pricing Inputs'!$B$29)+(I108*'Pricing Inputs'!$B$26*'Pricing Inputs'!$B$23),0) -> 0 | S108: =O108+P108+Q108+R108 -> 90.406 | U108: m6a.large | V108: 2 | W108: 8 | X108: Moderate right-size (source: zip (agent, current Azure environment)): avg CPU 7.8% x4 buffer = 2 vCPU target; avg RAM used 4.1GB x1.75 buffer = 7.1GB target (capped at current spec). Cheapest fit chosen. Never exceeds current spec. | Y108: No | Z108: zip (agent, current Azure environment)
A109: 105 | B109: AWS-SQL-PROD-01 (consolidates SSQLDBEdoc-Prod) | C109: Prod | D109: N/A - Consolidated | E109: 8 | F109: 64 | G109: 127 | H109: 640 | I109: =G109+H109 -> 767 | J109: Windows | K109: r6a.2xlarge | L109: 3-Yr No Upfront | M109: =IF(L109="3-Yr No Upfront",'Pricing Inputs'!$B$29,'Pricing Inputs'!$B$30) -> 730 | N109: =IF(U109="m7a.2xlarge",IF(L109="3-Yr No Upfront",'Pricing Inputs'!$E$18,'Pricing Inputs'!$D$18),IFERROR(INDEX('Pricing Inputs'!$D$6:$G$14,MATCH(U109,'Pricing Inputs'!$A$6:$A$14,0),IF(L109="3-Yr No Upfront",IF(J109="Windows",4,3),IF(J109="Windows",2,1))),"CHECK")) -> 0.65344 | O109: =M109*N109 -> 477.0112 | P109: =I109*'Pricing Inputs'!$B$22 -> 73.0184 | Q109: =I109*'Pricing Inputs'!$B$24*IF(OR(C109="Prod",C109="Prod/UAT/Dev"),'Pricing Inputs'!$B$31,'Pricing Inputs'!$B$32) -> 57.525 | R109: =IF(Y109="Yes",('Pricing Inputs'!$B$25*'Pricing Inputs'!$B$29)+(I109*'Pricing Inputs'!$B$26*'Pricing Inputs'!$B$23),0) -> 33.9392 | S109: =O109+P109+Q109+R109 -> 641.4938 | T109: SQL consolidation target. Sized from SSQLDBEdoc-Prod peak utilization (CPU 74.3% x 4 = 3.0 vCPU; RAM peak 31.2 GB x 1.25 buffer = 39 GB) rounded to nearest AMD r-family. Kept standalone — RAM already 90-97% utilized. Recommended for validation by the database administration team. | U109: r6a.2xlarge | V109: 8 | W109: 64 | X109: Already right-sized (SQL consolidation) - no change | Y109: Yes | Z109: N/A - sized separately
A110: 106 | B110: AWS-SQL-PROD-02 (consolidates SAddSQL-Prod + SSQLPROD) | C110: Prod | D110: N/A - Consolidated | E110: 16 | F110: 128 | G110: 255 | H110: 1280 | I110: =G110+H110 -> 1535 | J110: Windows | K110: r6a.4xlarge | L110: 3-Yr No Upfront | M110: =IF(L110="3-Yr No Upfront",'Pricing Inputs'!$B$29,'Pricing Inputs'!$B$30) -> 730 | N110: =IF(U110="m7a.2xlarge",IF(L110="3-Yr No Upfront",'Pricing Inputs'!$E$18,'Pricing Inputs'!$D$18),IFERROR(INDEX('Pricing Inputs'!$D$6:$G$14,MATCH(U110,'Pricing Inputs'!$A$6:$A$14,0),IF(L110="3-Yr No Upfront",IF(J110="Windows",4,3),IF(J110="Windows",2,1))),"CHECK")) -> 1.30688 | O110: =M110*N110 -> 954.0224 | P110: =I110*'Pricing Inputs'!$B$22 -> 146.132 | Q110: =I110*'Pricing Inputs'!$B$24*IF(OR(C110="Prod",C110="Prod/UAT/Dev"),'Pricing Inputs'!$B$31,'Pricing Inputs'!$B$32) -> 115.125 | R110: =IF(Y110="Yes",('Pricing Inputs'!$B$25*'Pricing Inputs'!$B$29)+(I110*'Pricing Inputs'!$B$26*'Pricing Inputs'!$B$23),0) -> 47.456 | S110: =O110+P110+Q110+R110 -> 1262.7354 | T110: SQL consolidation target. Combined right-sized need approximately 10-11 vCPU / 71 GB (sum of peak-utilization x 1.25 buffer for both source VMs) rounded to next AMD r-family size. Recommended for validation by the database administration team. | U110: r6a.4xlarge | V110: 16 | W110: 128 | X110: Already right-sized (SQL consolidation) - no change | Y110: Yes | Z110: N/A - sized separately
A111: 107 | B111: AWS-SQL-UAT-01 (consolidates SSQLDBEdoc-Test) | C111: UAT | D111: N/A - Consolidated | E111: 8 | F111: 64 | G111: 127 | H111: 256 | I111: =G111+H111 -> 383 | J111: Windows | K111: r6a.2xlarge | L111: On-Demand 12x5 | M111: =IF(L111="3-Yr No Upfront",'Pricing Inputs'!$B$29,'Pricing Inputs'!$B$30) -> 260 | N111: =IF(U111="m7a.2xlarge",IF(L111="3-Yr No Upfront",'Pricing Inputs'!$E$18,'Pricing Inputs'!$D$18),IFERROR(INDEX('Pricing Inputs'!$D$6:$G$14,MATCH(U111,'Pricing Inputs'!$A$6:$A$14,0),IF(L111="3-Yr No Upfront",IF(J111="Windows",4,3),IF(J111="Windows",2,1))),"CHECK")) -> 0.9152 | O111: =M111*N111 -> 237.952 | P111: =I111*'Pricing Inputs'!$B$22 -> 36.4616 | Q111: =I111*'Pricing Inputs'!$B$24*IF(OR(C111="Prod",C111="Prod/UAT/Dev"),'Pricing Inputs'!$B$31,'Pricing Inputs'!$B$32) -> 22.98 | R111: =IF(Y111="Yes",('Pricing Inputs'!$B$25*'Pricing Inputs'!$B$29)+(I111*'Pricing Inputs'!$B$26*'Pricing Inputs'!$B$23),0) -> 0 | S111: =O111+P111+Q111+R111 -> 297.3936 | T111: SQL consolidation target. Sized from SSQLDBEdoc-Test peak utilization (CPU 94.2% x 4 = 3.8 vCPU; RAM peak 29.15 GB x 1.25 buffer = 36.4 GB) rounded to nearest AMD r-family. Kept standalone — RAM already ~91% utilized. Recommended for validation by the database administration team. | U111: r6a.2xlarge | V111: 8 | W111: 64 | X111: Already right-sized (SQL consolidation) - no change | Y111: No | Z111: N/A - sized separately
A112: 108 | B112: AWS-SQL-UAT-02 (consolidates SAddSQL-Tst + SSQLTES) | C112: UAT | D112: N/A - Consolidated | E112: 8 | F112: 64 | G112: 227 | H112: 328 | I112: =G112+H112 -> 555 | J112: Windows | K112: r6a.2xlarge | L112: On-Demand 12x5 | M112: =IF(L112="3-Yr No Upfront",'Pricing Inputs'!$B$29,'Pricing Inputs'!$B$30) -> 260 | N112: =IF(U112="m7a.2xlarge",IF(L112="3-Yr No Upfront",'Pricing Inputs'!$E$18,'Pricing Inputs'!$D$18),IFERROR(INDEX('Pricing Inputs'!$D$6:$G$14,MATCH(U112,'Pricing Inputs'!$A$6:$A$14,0),IF(L112="3-Yr No Upfront",IF(J112="Windows",4,3),IF(J112="Windows",2,1))),"CHECK")) -> 0.9152 | O112: =M112*N112 -> 237.952 | P112: =I112*'Pricing Inputs'!$B$22 -> 52.836 | Q112: =I112*'Pricing Inputs'!$B$24*IF(OR(C112="Prod",C112="Prod/UAT/Dev"),'Pricing Inputs'!$B$31,'Pricing Inputs'!$B$32) -> 33.3 | R112: =IF(Y112="Yes",('Pricing Inputs'!$B$25*'Pricing Inputs'!$B$29)+(I112*'Pricing Inputs'!$B$26*'Pricing Inputs'!$B$23),0) -> 0 | S112: =O112+P112+Q112+R112 -> 324.088 | T112: SQL consolidation target. Combined right-sized need approximately 8.5 vCPU / 28.7 GB (sum of peak-utilization x 1.25 buffer). Recommended for validation by the database administration team. | U112: r6a.2xlarge | V112: 8 | W112: 64 | X112: Already right-sized (SQL consolidation) - no change | Y112: No | Z112: N/A - sized separately
A113: 109 | B113: AWS-ADDC-03 (new) | C113: Prod | D113: N/A - New Build | E113: 8 | F113: 32 | G113: 128 | H113: 0 | I113: =G113+H113 -> 128 | J113: Windows | K113: m7a.2xlarge | L113: 3-Yr No Upfront | M113: =IF(L113="3-Yr No Upfront",'Pricing Inputs'!$B$29,'Pricing Inputs'!$B$30) -> 730 | N113: =IF(U113="m7a.2xlarge",IF(L113="3-Yr No Upfront",'Pricing Inputs'!$E$18,'Pricing Inputs'!$D$18),IFERROR(INDEX('Pricing Inputs'!$D$6:$G$14,MATCH(U113,'Pricing Inputs'!$A$6:$A$14,0),IF(L113="3-Yr No Upfront",IF(J113="Windows",4,3),IF(J113="Windows",2,1))),"CHECK")) -> 0.6569 | O113: =M113*N113 -> 479.537 | P113: =I113*'Pricing Inputs'!$B$22 -> 12.1856 | Q113: =I113*'Pricing Inputs'!$B$24*IF(OR(C113="Prod",C113="Prod/UAT/Dev"),'Pricing Inputs'!$B$31,'Pricing Inputs'!$B$32) -> 9.6 | R113: =IF(Y113="Yes",('Pricing Inputs'!$B$25*'Pricing Inputs'!$B$29)+(I113*'Pricing Inputs'!$B$26*'Pricing Inputs'!$B$23),0) -> 22.6928 | S113: =O113+P113+Q113+R113 -> 524.0154 | T113: New additional AD Domain Controller (beyond SCDPT01/SCDPT02). Sized to match existing DC spec (2vCPU/8GB) since no separate sizing requirement given. | U113: m7a.2xlarge | V113: 8 | W113: 32 | X113: Specified sizing: m7a.2xlarge (7th-generation AMD). | Y113: Yes | Z113: N/A - sized separately
A114: 110 | B114: AWS-ADDC-04 (new) | C114: Prod | D114: N/A - New Build | E114: 8 | F114: 32 | G114: 128 | H114: 0 | I114: =G114+H114 -> 128 | J114: Windows | K114: m7a.2xlarge | L114: 3-Yr No Upfront | M114: =IF(L114="3-Yr No Upfront",'Pricing Inputs'!$B$29,'Pricing Inputs'!$B$30) -> 730 | N114: =IF(U114="m7a.2xlarge",IF(L114="3-Yr No Upfront",'Pricing Inputs'!$E$18,'Pricing Inputs'!$D$18),IFERROR(INDEX('Pricing Inputs'!$D$6:$G$14,MATCH(U114,'Pricing Inputs'!$A$6:$A$14,0),IF(L114="3-Yr No Upfront",IF(J114="Windows",4,3),IF(J114="Windows",2,1))),"CHECK")) -> 0.6569 | O114: =M114*N114 -> 479.537 | P114: =I114*'Pricing Inputs'!$B$22 -> 12.1856 | Q114: =I114*'Pricing Inputs'!$B$24*IF(OR(C114="Prod",C114="Prod/UAT/Dev"),'Pricing Inputs'!$B$31,'Pricing Inputs'!$B$32) -> 9.6 | R114: =IF(Y114="Yes",('Pricing Inputs'!$B$25*'Pricing Inputs'!$B$29)+(I114*'Pricing Inputs'!$B$26*'Pricing Inputs'!$B$23),0) -> 22.6928 | S114: =O114+P114+Q114+R114 -> 524.0154 | T114: New additional AD Domain Controller (beyond SCDPT01/SCDPT02). Sized to match existing DC spec (2vCPU/8GB) since no separate sizing requirement given. | U114: m7a.2xlarge | V114: 8 | W114: 32 | X114: Specified sizing: m7a.2xlarge (7th-generation AMD). | Y114: Yes | Z114: N/A - sized separately
B115: TOTAL | O115: =SUM(O5:O114) -> 19871.189 | P115: =SUM(P5:P114) -> 6269.396 | Q115: =SUM(Q5:Q114) -> 4748.505 | R115: =SUM(R5:R114) -> 2153.4704 | S115: =SUM(S5:S114) -> 33042.561

Sheet AWS Compute Cost
A1: AWS EC2 Compute Cost Summary
A2: Detail: see Server Inventory tab, column O (Monthly Compute $)
A4: Segment | B4: Instance Count | C4: Monthly Cost ($) | D4: Annual Cost ($) | E4: 3-Year Cost ($)
A5: Production (3-Yr No Upfront) | B5: =COUNTIF('Server Inventory'!$L$5:$L$114,"3-Yr No Upfront") -> 84 | C5: =SUMIF('Server Inventory'!$L$5:$L$114,"3-Yr No Upfront",'Server Inventory'!$O$5:$O$114) -> 17301.635 | D5: =C5*12 -> 207619.62 | E5: =C5*36 -> 622858.86
A6: UAT + Dev (On-Demand 12x5) | B6: =COUNTIF('Server Inventory'!$L$5:$L$114,"On-Demand 12x5") -> 26 | C6: =SUMIF('Server Inventory'!$L$5:$L$114,"On-Demand 12x5",'Server Inventory'!$O$5:$O$114) -> 2569.554 | D6: =C6*12 -> 30834.648 | E6: =C6*36 -> 92503.944
A7: TOTAL | B7: =SUM(B5:B6) -> 110 | C7: =SUM(C5:C6) -> 19871.189 | D7: =SUM(D5:D6) -> 238454.27 | E7: =SUM(E5:E6) -> 715362.81

Sheet AWS Storage Cost
A1: AWS EBS Storage Cost Summary
A2: gp3 storage, eu-central-1. Detail: see Server Inventory tab, column P
A4: Segment | B4: Instance Count | C4: Monthly Cost ($) | D4: Annual Cost ($) | E4: 3-Year Cost ($)
A5: Production (3-Yr No Upfront) | B5: =COUNTIF('Server Inventory'!$L$5:$L$114,"3-Yr No Upfront") -> 84 | C5: =SUMIF('Server Inventory'!$L$5:$L$114,"3-Yr No Upfront",'Server Inventory'!$P$5:$P$114) -> 5059.5944 | D5: =C5*12 -> 60715.133 | E5: =C5*36 -> 182145.4
A6: UAT + Dev (On-Demand 12x5) | B6: =COUNTIF('Server Inventory'!$L$5:$L$114,"On-Demand 12x5") -> 26 | C6: =SUMIF('Server Inventory'!$L$5:$L$114,"On-Demand 12x5",'Server Inventory'!$P$5:$P$114) -> 1209.8016 | D6: =C6*12 -> 14517.619 | E6: =C6*36 -> 43552.858
A7: TOTAL | B7: =SUM(B5:B6) -> 110 | C7: =SUM(C5:C6) -> 6269.396 | D7: =SUM(D5:D6) -> 75232.752 | E7: =SUM(E5:E6) -> 225698.26

Sheet AWS Backup Cost
A1: AWS Backup Cost Summary
A2: Prod: daily/30-day. UAT+Dev: weekly/1-month. Detail: see Server Inventory tab, column Q
A4: Segment | B4: Instance Count | C4: Monthly Cost ($) | D4: Annual Cost ($) | E4: 3-Year Cost ($)
A5: Production (3-Yr No Upfront) | B5: =COUNTIF('Server Inventory'!$L$5:$L$114,"3-Yr No Upfront") -> 84 | C5: =SUMIF('Server Inventory'!$L$5:$L$114,"3-Yr No Upfront",'Server Inventory'!$Q$5:$Q$114) -> 3986.025 | D5: =C5*12 -> 47832.3 | E5: =C5*36 -> 143496.9
A6: UAT + Dev (On-Demand 12x5) | B6: =COUNTIF('Server Inventory'!$L$5:$L$114,"On-Demand 12x5") -> 26 | C6: =SUMIF('Server Inventory'!$L$5:$L$114,"On-Demand 12x5",'Server Inventory'!$Q$5:$Q$114) -> 762.48 | D6: =C6*12 -> 9149.76 | E6: =C6*36 -> 27449.28
A7: TOTAL | B7: =SUM(B5:B6) -> 110 | C7: =SUM(C5:C6) -> 4748.505 | D7: =SUM(D5:D6) -> 56982.06 | E7: =SUM(E5:E6) -> 170946.18

Sheet AWS DRS Cost
A1: AWS DRS (Disaster Recovery) Cost — AWS Ireland (eu-west-1)
A2: Production servers only (Environment = "Prod" tag, 64 servers - excludes shared Prod/UAT/Dev). Replication fee + staging storage (20% of source disk).
A4: Segment | B4: Instance Count | C4: Monthly Cost ($) | D4: Annual Cost ($) | E4: 3-Year Cost ($)
A5: Production servers (Env=Prod, DRS to eu-west-1) | B5: =COUNTIF('Server Inventory'!$Y$5:$Y$114,"Yes") -> 64 | C5: =SUMIF('Server Inventory'!$Y$5:$Y$114,"Yes",'Server Inventory'!$R$5:$R$114) -> 2153.4704 | D5: =C5*12 -> 25841.645 | E5: =C5*36 -> 77524.934
A7: Note: Excludes recovery-instance and drill-testing compute cost, which is only incurred during an actual failover or scheduled DR test — not a steady-state monthly charge. A separate DR-test cost line can be added if required.

Sheet Network Cost
A1: AWS Network Cost — Transit Gateway
A2: 4 Transit Gateway attachments, 100 GB/month data transfer each
A4: Number of TGW attachments | B4: 4
A5: Data transfer per attachment (GB/month) | B5: 100
A6: TGW attachment rate ($/hour) | B6: ='Pricing Inputs'!$B$27 -> 0.06
A7: TGW data processing rate ($/GB) | B7: ='Pricing Inputs'!$B$28 -> 0.02
A8: Hours per month | B8: ='Pricing Inputs'!$B$29 -> 730
A10: Monthly attachment cost ($) | B10: =B4*B6*B8 -> 175.2
A11: Monthly data processing cost ($) | B11: =B4*B5*B7 -> 8
A12: TOTAL Monthly Network Cost ($) | B12: =B10+B11 -> 183.2
A13: TOTAL Annual Network Cost ($) | B13: =B12*12 -> 2198.4
A14: TOTAL 3-Year Network Cost ($) | B14: =B12*36 -> 6595.2
A16: Transit Gateway - DR cross-region attachment (Frankfurt ↔ Ireland) | B16: 38.5
A17: Cross-region peering attachments are billed at a different rate than standard same-region attachments.
A19: TOTAL Monthly Network Cost incl. DR attachment ($) | B19: =B12+B16 -> 221.7
A20: TOTAL Annual Network Cost incl. DR attachment ($) | B20: =B19*12 -> 2660.4
A21: TOTAL 3-Year Network Cost incl. DR attachment ($) | B21: =B19*36 -> 7981.2

Sheet Azure Baseline
A1: Azure Current-State Baseline Cost (EUR)
A2: Azure infrastructure cost only. Managed Services is a separate vendor/IMS cost, not comparable to AWS infrastructure spend, and is excluded from this baseline. Actuals: Dec-2025, Jan-2026 only. Feb-Dec 2026 held flat at the average of the two known months.
A4: Month | B4: Managed Services (€) | C4: Azure Tenant (€) | D4: Azure Infra Cost - used for TCO (€) | E4: Source | F4: Total (USD)
A5: Dec-2025 | B5: 12046.83 | C5: 30911.06 | D5: =C5 -> 30911.06 | E5: Actual invoice | F5: =D5*'Pricing Inputs'!$B$37 -> 35238.608
A6: Jan-2026 | B6: 12046.83 | C6: 32925.61 | D6: =C6 -> 32925.61 | E6: Actual invoice | F6: =D6*'Pricing Inputs'!$B$37 -> 37535.195
A7: Feb-2026 | B7: =AVERAGE($B$5:$B$6) -> 12046.83 | C7: =AVERAGE($C$5:$C$6) -> 31918.335 | D7: =C7 -> 31918.335 | E7: ASSUMPTION - held flat at avg of Dec/Jan actuals | F7: =D7*'Pricing Inputs'!$B$37 -> 36386.902
A8: Mar-2026 | B8: =AVERAGE($B$5:$B$6) -> 12046.83 | C8: =AVERAGE($C$5:$C$6) -> 31918.335 | D8: =C8 -> 31918.335 | E8: ASSUMPTION - held flat at avg of Dec/Jan actuals | F8: =D8*'Pricing Inputs'!$B$37 -> 36386.902
A9: Apr-2026 | B9: =AVERAGE($B$5:$B$6) -> 12046.83 | C9: =AVERAGE($C$5:$C$6) -> 31918.335 | D9: =C9 -> 31918.335 | E9: ASSUMPTION - held flat at avg of Dec/Jan actuals | F9: =D9*'Pricing Inputs'!$B$37 -> 36386.902
A10: May-2026 | B10: =AVERAGE($B$5:$B$6) -> 12046.83 | C10: =AVERAGE($C$5:$C$6) -> 31918.335 | D10: =C10 -> 31918.335 | E10: ASSUMPTION - held flat at avg of Dec/Jan actuals | F10: =D10*'Pricing Inputs'!$B$37 -> 36386.902
A11: Jun-2026 | B11: =AVERAGE($B$5:$B$6) -> 12046.83 | C11: =AVERAGE($C$5:$C$6) -> 31918.335 | D11: =C11 -> 31918.335 | E11: ASSUMPTION - held flat at avg of Dec/Jan actuals | F11: =D11*'Pricing Inputs'!$B$37 -> 36386.902
A12: Jul-2026 | B12: =AVERAGE($B$5:$B$6) -> 12046.83 | C12: =AVERAGE($C$5:$C$6) -> 31918.335 | D12: =C12 -> 31918.335 | E12: ASSUMPTION - held flat at avg of Dec/Jan actuals | F12: =D12*'Pricing Inputs'!$B$37 -> 36386.902
A13: Aug-2026 | B13: =AVERAGE($B$5:$B$6) -> 12046.83 | C13: =AVERAGE($C$5:$C$6) -> 31918.335 | D13: =C13 -> 31918.335 | E13: ASSUMPTION - held flat at avg of Dec/Jan actuals | F13: =D13*'Pricing Inputs'!$B$37 -> 36386.902
A14: Sep-2026 | B14: =AVERAGE($B$5:$B$6) -> 12046.83 | C14: =AVERAGE($C$5:$C$6) -> 31918.335 | D14: =C14 -> 31918.335 | E14: ASSUMPTION - held flat at avg of Dec/Jan actuals | F14: =D14*'Pricing Inputs'!$B$37 -> 36386.902
A15: Oct-2026 | B15: =AVERAGE($B$5:$B$6) -> 12046.83 | C15: =AVERAGE($C$5:$C$6) -> 31918.335 | D15: =C15 -> 31918.335 | E15: ASSUMPTION - held flat at avg of Dec/Jan actuals | F15: =D15*'Pricing Inputs'!$B$37 -> 36386.902
A16: Nov-2026 | B16: =AVERAGE($B$5:$B$6) -> 12046.83 | C16: =AVERAGE($C$5:$C$6) -> 31918.335 | D16: =C16 -> 31918.335 | E16: ASSUMPTION - held flat at avg of Dec/Jan actuals | F16: =D16*'Pricing Inputs'!$B$37 -> 36386.902
A17: Dec-2026 | B17: =AVERAGE($B$5:$B$6) -> 12046.83 | C17: =AVERAGE($C$5:$C$6) -> 31918.335 | D17: =C17 -> 31918.335 | E17: ASSUMPTION - held flat at avg of Dec/Jan actuals | F17: =D17*'Pricing Inputs'!$B$37 -> 36386.902
A18: TOTAL (12 months) | B18: =SUM(B5:B17) -> 156608.79 | C18: =SUM(C5:C17) -> 414938.36 | D18: =SUM(D5:D17) -> 414938.36
A19: Managed Services (excluded from TCO - vendor/IMS cost) | B19: =SUM(B5:B17) -> 156608.79
A20: Annualized Azure Baseline (€/year) | B20: =D18 -> 414938.36 | E20: Annualized (USD) | F20: =B20*'Pricing Inputs'!$B$37 -> 473029.72
A21: 3-Year Azure Baseline (€, flat projection) | B21: =B20*3 -> 1244815.1 | E21: 3-Year (USD) | F21: =B21*'Pricing Inputs'!$B$37 -> 1419089.2
A23: Figures are shown in EUR and USD using the FX rate on the Pricing Inputs tab.

Sheet TCO Summary
A1: 3-Year TCO Summary — Azure (Current) vs AWS (Proposed)
A2: All figures shown in EUR and USD. FX rate: see Pricing Inputs!B31 (update there to refresh every number below).
A4: AWS COST BREAKDOWN (USD) — 3-Year
A5: Cost Category | B5: Monthly ($) | C5: Annual ($) | D5: 3-Year ($) | E5: Monthly (€) | F5: Annual (€) | G5: 3-Year (€)
A6: EC2 Compute | B6: ='AWS Compute Cost'!C7 -> 19871.189 | C6: =B6*12 -> 238454.27 | D6: =B6*36 -> 715362.81 | E6: =B6/'Pricing Inputs'!$B$37 -> 17430.868 | F6: =C6/'Pricing Inputs'!$B$37 -> 209170.41 | G6: =D6/'Pricing Inputs'!$B$37 -> 627511.23
A7: EBS Storage | B7: ='AWS Storage Cost'!C7 -> 6269.396 | C7: =B7*12 -> 75232.752 | D7: =B7*36 -> 225698.26 | E7: =B7/'Pricing Inputs'!$B$37 -> 5499.4702 | F7: =C7/'Pricing Inputs'!$B$37 -> 65993.642 | G7: =D7/'Pricing Inputs'!$B$37 -> 197980.93
A8: AWS Backup | B8: ='AWS Backup Cost'!C7 -> 4748.505 | C8: =B8*12 -> 56982.06 | D8: =B8*36 -> 170946.18 | E8: =B8/'Pricing Inputs'!$B$37 -> 4165.3553 | F8: =C8/'Pricing Inputs'!$B$37 -> 49984.263 | G8: =D8/'Pricing Inputs'!$B$37 -> 149952.79
A9: AWS DRS (Ireland, Prod only) | B9: ='AWS DRS Cost'!C5 -> 2153.4704 | C9: =B9*12 -> 25841.645 | D9: =B9*36 -> 77524.934 | E9: =B9/'Pricing Inputs'!$B$37 -> 1889.0091 | F9: =C9/'Pricing Inputs'!$B$37 -> 22668.109 | G9: =D9/'Pricing Inputs'!$B$37 -> 68004.328
A10: Network (Transit Gateway) | B10: ='Network Cost'!B19 -> 221.7 | C10: ='Network Cost'!B20 -> 2660.4 | D10: ='Network Cost'!B21 -> 7981.2 | E10: =B10/'Pricing Inputs'!$B$37 -> 194.47368 | F10: =C10/'Pricing Inputs'!$B$37 -> 2333.6842 | G10: =D10/'Pricing Inputs'!$B$37 -> 7001.0526
A11: TOTAL AWS COST | B11: =SUM(B6:B10) -> 33264.261 | C11: =SUM(C6:C10) -> 399171.13 | D11: =SUM(D6:D10) -> 1197513.4 | E11: =SUM(E6:E10) -> 29179.176 | F11: =SUM(F6:F10) -> 350150.11 | G11: =SUM(G6:G10) -> 1050450.3
A14: AZURE BASELINE (EUR) — 3-Year
A15: Cost Category | B15: Annualized (€) | C15: 3-Year (€) | D15: Annualized ($) | E15: 3-Year ($)
A16: Azure Infrastructure Cost (Managed Services excluded) | B16: ='Azure Baseline'!B20 -> 414938.36 | C16: ='Azure Baseline'!B21 -> 1244815.1 | D16: =B16*'Pricing Inputs'!$B$37 -> 473029.72 | E16: =C16*'Pricing Inputs'!$B$37 -> 1419089.2
A17: Note: Feb–Dec 2026 uses an assumed flat continuation of Dec/Jan actuals — see Azure Baseline tab.
A20: SIDE-BY-SIDE COMPARISON (No FX conversion applied)
B21: Azure (€) | C21: Azure ($) | D21: AWS ($) | E21: AWS (€)
