Workbook

Sheet Meeting Outcomes & Summary
A1: Rainbow Hospitals – Final TCO (30-Apr-2026 — v1.3, PDF-validated + AA recon) | Primary: Hyderabad | DR: Mumbai
B3: Primary: Hyderabad (ap-south-2) | DR: Mumbai (ap-south-1) Multi-Region Active-Passive
B5: ✅ Confirmed Decisions from Chari Meeting (22-Apr-2026)
B6: 1. SAP Strategy: SAP servers hosted by 3rd party vendor (HANA upgrade ongoing)
B7: BUT: Chari clarified — 'Old ECC data everything should be moved to AWS' → SAP apps included as-is
B8: 2. Primary DC: Hyderabad (ap-south-2) — active production
B9: 3. DR: Mumbai (ap-south-1) — Multi-Region Active-Passive with continuous replication
B10: 4. Chari requested quotes for BOTH Active-Active AND Active-Passive options
B11: 5. HIS: Lift-and-shift approach. Legacy HIS servers NOT migrated (decommission on-prem)
B12: 6. MongoDB: AWS Marketplace-based deployment agreed
B13: 7. Licensing: AWS License Included for Windows + SQL Server (no BYOL)
B14: 8. Biometric, Blood Bank → Windows SQL stays (Linux SQL not feasible immediately)
B15: 9. Security: AWS Inspector replaces EDR | AWS Backup replaces CommVault | Palo Alto via Marketplace
... B64: 7. SAP HANA r6i.2xlarge is below SAP cert threshold — discuss with Chari
A66: 📝 Changes in v1.2 (30-Apr-2026) — PDF Validation Pass
A67: • Validated against AWS Pricing Calculator export dated 30-Apr-2026 (AWS-TCO-30April.pdf).
A68: • Primary TCO Hyderabad: 7 EBS allocations corrected; SAP-DevTesting instance updated m6a.2xlarge → r6i.xlarge per AWS Calculator. Total $/mo unchanged at $12,450.43.
A69: • DR TCO Mumbai: RAINDC03 DR instance label corrected m6i.large → m6i.xlarge (cost was already correct at $226.67). Total unchanged at $8,281.29.
A70: • SuppServices4ExistingHIS: VPC HYD $271.14 → $329.83; VPC Mumbai DR $137.76 → $329.83; Inter-region DT $192.07 → $176.13; added S3 DR (Mumbai 2TB CRR) $56.60. Net total change: $3,657.05 → $3,948.48 (+$291.43).
A71: • Marketplace Offerings: validated within $0.38 rounding tolerance, no edits.
A72: • Existing AWS HMS Phase 2: DEPLOYSERV01 $10.13 → $10.87; Grafana Monitoring $71.21 → $63.32. Net total change: $6,216.29 → $6,209.14 (-$7.15). Region typo at CloudWatch DR row corrected (0 → Mumbai).
A73: • Consolidated Master View, Consolidated Summary, Master KareXpert, Master MyHealthcare: re-pointed Supporting Services reference from 'Supporting Services'!F28 → 'SuppServices4ExistingHIS'!F29 (PDF-validated source).
A74: • Active-Active vs Passive: DR Supporting Services SUMPRODUCT re-pointed to SuppServices4ExistingHIS for consistency.
A75: • 'Supporting Services' sheet (with Logically Air-Gapped Vault row added in v1.1) is preserved as a separate scenario sheet but is no longer referenced by consolidated views — calculator-validated baseline is the source of truth in v1.2.
A77: 📝 Changes in v1.3 (30-Apr-2026) — Active-Active Supporting Services Reconciliation
A78: • Active-Active vs Passive sheet: AA Mumbai supporting services updated to reflect v1.2 PDF validation and correct internal inconsistencies.
... A85: • AA total DR cost: $12,818.24 → $13,125.30. Active-Active is now correctly higher than Active-Passive on like-for-like services (the residual lower AA total versus AP total reflects only that AA does not require AWS DRS at $1,191.28).

Sheet Master - KareXpert Option
A1: Rainbow Hospitals — Complete TCO with KareXpert Option
B3: Primary: Hyderabad | DR: Mumbai Active-Passive | HIS vendor-specific costs added
B5: Category | C5: Monthly (USD) | D5: Annual (USD) | E5: Notes
B6: ControlS - Production Servers (CSP 3yr) | C6: ='Primary TCO - Hyderabad'!Q30 -> 10962.73 | D6: =C6*12 -> 131552.76 | E6: Existing ControlS migration servers.
B7: ControlS - Non-Prod Servers (OD best) | C7: ='Primary TCO - Hyderabad'!Q31 -> 1387.59 | D7: =C7*12 -> 16651.08 | E7: Cheaper of 75% util or 8hr/day.
B8: DR - Mumbai (Active-Passive) | C8: ='DR TCO - Mumbai'!O14 -> 8281.29 | D8: =C8*12 -> 99375.48 | E8: 10 critical servers pilot-light.
B9: Supporting Services (HYD + Mumbai) | C9: =SuppServices4ExistingHIS!F29 -> 3948.48 | D9: =C9*12 -> 47381.76 | E9: Inspector, Backup 365d, WAF, DRS.
B10: Marketplace (Palo Alto + MongoDB) | C10: ='Marketplace Offerings'!F17 -> 5173.08 | D10: =C10*12 -> 62076.96 | E10: Palo Alto HA + MongoDB Atlas.
B11: Existing AWS HMS (Phase 2) | C11: ='Existing AWS HMS (Phase 2)'!G33 -> 6209.14 | D11: =C11*12 -> 74509.68 | E11: Moving Mumbai → HYD + DR Mumbai.
B12: NEW HIS — KareXpert Option | C12: ='HIS BOM - KareXpert'!I25 -> 4768.17 | D12: =C12*12 -> 57218.04 | E12: See 'HIS BOM - KareXpert' sheet for detail.
B13: GRAND TOTAL (KareXpert Option) | C13: =SUM(C6:C12) -> 40730.48 | D13: =C13*12 -> 488765.76 | E13: Complete Rainbow AWS Landscape
B15: HIS Vendor Cost Comparison
B16: MyHealthcare (MHEA): $8,382.62/mo (214 Graviton VMs, microservices on EC2)
B17: KareXpert: $4,768.17/mo (24 EKS worker nodes, Kubernetes-based)
B18: Difference: $3,614.45/mo ($43,373.40/yr)
B20: ⚠️ All HIS EC2 rates are estimates — validate in AWS Pricing Calculator before submission.
B21: ⚠️ KareXpert MongoDB M60 may REPLACE existing Atlas clusters — clarify with vendor.
B26: KareXpert DR Rough 1,500 to 2,500 USD per month

Sheet Master - MyHealthcare Option
A1: Rainbow Hospitals — Complete TCO with MyHealthcare Option
B3: Primary: Hyderabad | DR: Mumbai Active-Passive | HIS vendor-specific costs added
B5: Category | C5: Monthly (USD) | D5: Annual (USD) | E5: Notes
B6: ControlS - Production Servers (CSP 3yr) | C6: ='Primary TCO - Hyderabad'!Q30 -> 10962.73 | D6: =C6*12 -> 131552.76 | E6: Existing ControlS migration servers.
B7: ControlS - Non-Prod Servers (OD best) | C7: ='Primary TCO - Hyderabad'!Q31 -> 1387.59 | D7: =C7*12 -> 16651.08 | E7: Cheaper of 75% util or 8hr/day.
B8: DR - Mumbai (Active-Passive) | C8: ='DR TCO - Mumbai'!O14 -> 8281.29 | D8: =C8*12 -> 99375.48 | E8: 10 critical servers pilot-light.
B9: Supporting Services (HYD + Mumbai) | C9: =SuppServices4ExistingHIS!F29 -> 3948.48 | D9: =C9*12 -> 47381.76 | E9: Inspector, Backup 365d, WAF, DRS.
B10: Marketplace (Palo Alto + MongoDB) | C10: ='Marketplace Offerings'!F17 -> 5173.08 | D10: =C10*12 -> 62076.96 | E10: Palo Alto HA + MongoDB Atlas.
B11: Existing AWS HMS (Phase 2) | C11: ='Existing AWS HMS (Phase 2)'!G33 -> 6209.14 | D11: =C11*12 -> 74509.68 | E11: Moving Mumbai → HYD + DR Mumbai.
B12: NEW HIS — MyHealthcare Option | C12: ='HIS BOM - MyHealthcare'!I30 -> 8382.62 | D12: =C12*12 -> 100591.44 | E12: See 'HIS BOM - MyHealthcare' sheet for detail.
B13: GRAND TOTAL (MyHealthcare Option) | C13: =SUM(C6:C12) -> 44344.93 | D13: =C13*12 -> 532139.16 | E13: Complete Rainbow AWS Landscape
B15: HIS Vendor Cost Comparison
B16: MyHealthcare (MHEA): $8,382.62/mo (214 Graviton VMs, microservices on EC2)
B17: KareXpert: $4,768.17/mo (24 EKS worker nodes, Kubernetes-based)
B18: Difference: $3,614.45/mo ($43,373.40/yr)
B20: ⚠️ All HIS EC2 rates are estimates — validate in AWS Pricing Calculator before submission.
B21: ⚠️ KareXpert MongoDB M60 may REPLACE existing Atlas clusters — clarify with vendor.
B26: MyHealthcare DR rough estimate 3,000 to 4,000 USD per month

Sheet MyHealthCommercial Breakdown 
B3: Breakup | C3: Annual Cost
B4: Cntrl S Infra | C4: ='Consolidated Master View'!H127+'Consolidated Master View'!H128 -> 148203.84 | I4: MAP Credits
B5: DR | C5: ='Consolidated Master View'!H129 -> 99375.48 | I5: =B4 -> Cntrl S Infra | J5: =C4 -> 148203.84
B6: Shared Services | C6: ='Consolidated Summary'!D9 -> 47381.76 | I6: =B5 -> DR | J6: =C5 -> 99375.48
B7: Marketplace | C7: ='Consolidated Master View'!H132 -> 62076.96 | I7: =B6 -> Shared Services | J7: =C6 -> 47381.76
B8: Existing HIS | C8: ='Consolidated Summary'!D11 -> 74509.68 | D8: Existing application resources will get optimized only snapshot will be there. | I8: =B9 -> MyHealthcare | J8: =C9 -> 100591.44
B9: MyHealthcare | C9: ='Master - MyHealthcare Option'!D12 -> 100591.44 | I9: =B10 -> MyHealthcare DR (approx) $4,000 MRR | J9: =C10 -> 48000
B10: MyHealthcare DR (approx) $4,000 MRR | C10: =4000*12 -> 48000
B11: Total Cost (Existing + Cntrl S + DR + Marketplace + ) | C11: =SUM(C4:C10) -> 580139.16 | I11: Total ARR | J11: =SUM(J5:J9) -> 443552.52
B13: Total MAP Credits | C13: =C27 -> 104654.18
B14: Minfy Discount | C14: =3%*(C11-C7) -> 15541.866
B15: Total Effective Cost Year 1 | C15: =C11-C13-C14 -> 459943.12
B16: MS Charges | C16: =(C11-C7)*10% -> 51806.22
B17: Total TCO Including MS Year 1 with Marketplace | C17: =C15+C16 -> 511749.34
B18: Total Effective Cost Year 1 Without Marketplace (SaaS - MongoDB + PaloAlto) | C18: =(C11-C7)-(C13+C14)+C16 -> 449672.38
B20: Note - No Discount/Credits will be applied on Marketplace
B21: Note: Optimize the Existing HIS running in AWS, only the snapshots will be there.
B23: MAP Credits | C23: =J11*15% -> 66532.878 | E23: 3294.85 | F23: =E23*12 -> 39538.2
B24: SAP Credits | C24: =F25*50% -> 31000.5 | E24: 1871.9 | F24: =E24*12 -> 22462.8
B25: Windows | C25: =F30 -> 7120.8 | E25: SAP | F25: =SUM(F23:F24) -> 62001
C27: =SUM(C23:C25) -> 104654.18 | D27: windows | E27: 3295 | F27: =E27*12 -> 39540
E28: 2639 | F28: =E28*12 -> 31668
F29: =F27+F28 -> 71208
F30: =F29*10% -> 7120.8

Sheet KareXpeCommercial Breakdown 
B3: Breakup | C3: Annual Cost
B4: Cntrl S Infra | C4: ='Consolidated Master View'!H127+'Consolidated Master View'!H128 -> 148203.84
B5: DR | C5: ='Consolidated Master View'!H129 -> 99375.48
B6: Shared Services | C6: ='Consolidated Summary'!D9 -> 47381.76 | H6: MAP Credits
B7: Marketplace | C7: ='Consolidated Master View'!H132 -> 62076.96 | H7: =B4 -> Cntrl S Infra | I7: =C4 -> 148203.84 | K7: 3294.85 | L7: =K7*12 -> 39538.2
B8: Existing AWS HIS | C8: ='Consolidated Summary'!D11 -> 74509.68 | D8: Existing application resources will get optimized only snapshot will be there. | H8: =B5 -> DR | I8: =C5 -> 99375.48 | K8: 1871.9 | L8: =K8*12 -> 22462.8
B9: KareXpert | C9: ='Master - KareXpert Option'!D12 -> 57218.04 | H9: =B6 -> Shared Services | I9: =C6 -> 47381.76 | K9: SAP Total ARR | L9: =SUM(L7:L8) -> 62001
B10: KareXpert DR (Approx) - $2,500 / MRR | C10: =2500*12 -> 30000 | H10: KareExpert | I10: =C9 -> 57218.04
B11: Total Cost (Existing + Cntrl S + DR + Marketplace + New HIS) | C11: =SUM(C4:C10) -> 518765.76 | H11: KareExpert DR | I11: =C10 -> 30000
H12: Total | I12: =SUM(I7:I11) -> 382179.12 | K12: 3295 | L12: =K12*12 -> 39540
B13: Total MAP Credits | C13: =C29 -> 95448.168 | K13: 2639 | L13: =K13*12 -> 31668
B14: Minfy Discount | C14: =3%*(C11-C7) -> 13700.664 | L14: =L12+L13 -> 71208
B15: AWS Total Effective Cost for Year 1 | C15: =C11-C13-C14 -> 409616.93 | K15: Total Win | L15: =L14*10% -> 7120.8
B16: Minfy MS Cost | C16: =(C11-C7)*10% -> 45668.88
B17: Total TCO Including MS Year 1 with Marketplace | C17: =C15+C16 -> 455285.81
B18: Total Effective Cost Year 1 Without Marketplace (SaaS - MongoDB + PaloAlto) | C18: =(C11-C7)-(C13+C14)+C16 -> 393208.85
B22: Note - No Discount/Credits will be applied on Marketplace
B23: Note: Optimize the Existing HIS running in AWS, only the snapshots will be there.
B25: MAP Credits | C25: =I12*15% -> 57326.868
B26: SAP Credits | C26: =L9*50% -> 31000.5
B27: Windows | C27: =L15 -> 7120.8
C29: =SUM(C25:C27) -> 95448.168 | D29: windows

Sheet Commercial Breakdown
B3: Breakup | C3: Annual Cost
B4: Cntrl S Infra | C4: ='Consolidated Master View'!H127+'Consolidated Master View'!H128 -> 148203.84
B5: DR | C5: ='Consolidated Master View'!H129 -> 99375.48
B6: Shared Services | C6: ='Consolidated Summary'!D9 -> 47381.76
B7: Marketplace | C7: ='Consolidated Master View'!H132 -> 62076.96
B8: AD&PACS | C8: ='Consolidated Master View'!H133 -> 0
B9: Existing AWS | C9: ='Consolidated Master View'!H130 -> 74509.68
B10: Total Cost (Existing + Cntrl S + DR + Marketplace + AD&PACS) | C10: =SUM(C4:C9) -> 431547.72
B12: Total MAP Credits | C12: =C24 -> 93541.914
B13: Minfy Discount | C13: =3%*(C10-C7) -> 11084.123
B14: Total Effective Cost Year 1 | C14: =C10-C12-C13 -> 326921.68
B15: Total Effective Cost Year 1 Without Marketplace (SaaS - MongoDB + PaloAlto) | C15: =C10-C7 -> 369470.76
B17: Note - No Discount/Credits will be applied on Marketplace
B20: MAP Credits | C20: =C15*15% -> 55420.614 | E20: 3294.85 | F20: =E20*12 -> 39538.2
B21: SAP Credits | C21: =F22*50% -> 31000.5 | E21: 1871.9 | F21: =E21*12 -> 22462.8
B22: DA | C22: =F27 -> 7120.8 | E22: SAP | F22: =SUM(F20:F21) -> 62001
C24: =SUM(C20:C22) -> 93541.914 | D24: windows | E24: 3295 | F24: =E24*12 -> 39540
E25: 2639 | F25: =E25*12 -> 31668
F26: =F24+F25 -> 71208
F27: =F26*10% -> 7120.8

Sheet Consolidated Master View
A1: Rainbow Hospitals — Consolidated Master Pricing View (30-Apr-2026 — v1.3)
A2: All EC2 prices validated against AWS Pricing Calculator export (24-Apr-2026). Filter 'Hosting Environment' for split views.
A4: S.No | B4: Server / Service | C4: Hosting Env | D4: Category | E4: Region | F4: Instance | G4: Monthly (USD) | H4: Annual (USD) | I4: Scope | J4: Notes
A5: CtrlS PRODUCTION (PDF Validated)
A6: 1 | B6: RAINDC03 | C6: CtrlS → AWS | D6: EC2 - Prod | E6: Hyderabad | F6: m6i.xlarge | G6: 226.67 | H6: =G6*12 -> 2720.04 | I6: In Scope | J6: AD Primary DC
A7: 2 | B7: RAINDC02 | C7: CtrlS → AWS | D7: EC2 - Prod | E7: Hyderabad | F7: m6i.xlarge | G7: 226.67 | H7: =G7*12 -> 2720.04 | I7: In Scope | J7: AD Secondary DC
A8: 3 | B8: Rchbbserver | C8: CtrlS → AWS | D8: EC2 - Prod | E8: Hyderabad | F8: m6a.4xlarge | G8: 2193.63 | H8: =G8*12 -> 26323.56 | I8: In Scope | J8: Blood Bank + SQL Std
A9: 4 | B9: Rainbow_MRD | C9: CtrlS → AWS | D9: EC2 - Prod | E9: Hyderabad | F9: c6a.8xlarge | G9: 2270.91 | H9: =G9*12 -> 27250.92 | I9: In Scope | J9: MRD OCR
A10: 5 | B10: RCHAEON | C10: CtrlS → AWS | D10: EC2 - Prod | E10: Hyderabad | F10: r6a.4xlarge | G10: 2301.86 | H10: =G10*12 -> 27622.32 | I10: In Scope | J10: Biometric + SQL Std
A11: 6 | B11: RainbowRPA | C11: CtrlS → AWS | D11: EC2 - Prod | E11: Hyderabad | F11: m6a.2xlarge | G11: 382.08 | H11: =G11*12 -> 4584.96 | I11: In Scope | J11: RPA Reporting
A12: 7 | B12: SAP_PI_PRD | C12: CtrlS → AWS | D12: EC2 - Prod (SAP) | E12: Hyderabad | F12: m6a.4xlarge | G12: 830.11 | H12: =G12*12 -> 9961.32 | I12: In Scope | J12: SAP PI/PO
A13: 8 | B13: repsapGRP | C13: CtrlS → AWS | D13: EC2 - Prod (SAP) | E13: Hyderabad | F13: r6a.2xlarge | G13: 598.01 | H13: =G13*12 -> 7176.12 | I13: In Scope | J13: SAP ECC Node A (was HANA)
A14: 9 | B14: repsapAPP | C14: CtrlS → AWS | D14: EC2 - Prod (SAP) | E14: Hyderabad | F14: r6a.2xlarge | G14: 479.45 | H14: =G14*12 -> 5753.4 | I14: In Scope | J14: SAP ECC Node B (was HANA)
A15: 10 | B15: RCHSOLMAN72 | C15: CtrlS → AWS | D15: EC2 - Prod (SAP) | E15: Hyderabad | F15: r6a.2xlarge | G15: 511.37 | H15: =G15*12 -> 6136.44 | I15: In Scope | J15: SolMan (no longer HANA)
A16: 11 | B16: Rainbow-NC-VCiso | C16: CtrlS → AWS | D16: EC2 - Prod | E16: Hyderabad | F16: m6a.2xlarge | G16: 190.96 | H16: =G16*12 -> 2291.52 | I16: In Scope | J16: vCISO Security
A17: 12 | B17: Rainbow-NC-Syslog | C17: CtrlS → AWS | D17: EC2 - Prod | E17: Hyderabad | F17: c6a.2xlarge | G17: 168.73 | H17: =G17*12 -> 2024.76 | I17: In Scope | J17: Syslog
... A19: 14 | B19: mobileapp | C19: CtrlS → AWS | D19: EC2 - Prod | E19: Hyderabad | F19: m6a.4xlarge | G19: 276.68 | H19: =G19*12 -> 3320.16 | I19: In Scope | J19: Mobile App
A20: CtrlS NON-PRODUCTION (PDF Validated)
A21: 15 | B21: RCHECCDEC | C21: CtrlS → AWS | D21: EC2 - Non-Prod (SAP) | E21: Hyderabad | F21: m6a.xlarge | G21: 139.53 | H21: =G21*12 -> 1674.36 | I21: In Scope | J21: SAP ECC QA/Dev
A22: 16 | B22: RNBWHYDFDBK | C22: CtrlS → AWS | D22: EC2 - Non-Prod | E22: Hyderabad | F22: t3.medium | G22: 24.41 | H22: =G22*12 -> 292.92 | I22: In Scope | J22: Feedback
A23: 17 | B23: RainbowC52431 | C23: CtrlS → AWS | D23: EC2 - Non-Prod | E23: Hyderabad | F23: t3.xlarge | G23: 51.48 | H23: =G23*12 -> 617.76 | I23: In Scope | J23: ICU Monitor
A24: 18 | B24: SAP_PI_DEV | C24: CtrlS → AWS | D24: EC2 - Non-Prod (SAP) | E24: Hyderabad | F24: m6a.xlarge | G24: 98.9 | H24: =G24*12 -> 1186.8 | I24: In Scope | J24: SAP PI Dev
A25: 19 | B25: sapgst | C25: CtrlS → AWS | D25: EC2 - Non-Prod (SAP) | E25: Hyderabad | F25: m6a.xlarge | G25: 93.78 | H25: =G25*12 -> 1125.36 | I25: In Scope | J25: SAP GST
A26: 20 | B26: BIUAT-MIS | C26: CtrlS → AWS | D26: EC2 - Non-Prod | E26: Hyderabad | F26: t3.xlarge | G26: 49.82 | H26: =G26*12 -> 597.84 | I26: In Scope | J26: BI UAT
A27: 21 | B27: Manage_Engine | C27: CtrlS → AWS | D27: EC2 - Non-Prod | E27: Hyderabad | F27: t3.2xlarge | G27: 138.08 | H27: =G27*12 -> 1656.96 | I27: In Scope | J27: ManageEngine
A28: 22 | B28: Rainbow-HIS-UAT | C28: CtrlS → AWS | D28: EC2 - Non-Prod | E28: Hyderabad | F28: r6a.2xlarge | G28: 276.36 | H28: =G28*12 -> 3316.32 | I28: In Scope | J28: HIS UAT
A29: 23 | B29: SAP-DevTesting | C29: CtrlS → AWS | D29: EC2 - Non-Prod (SAP) | E29: Hyderabad | F29: m6a.2xlarge | G29: 141.15 | H29: =G29*12 -> 1693.8 | I29: In Scope | J29: SAP ECC Dev (was HANA)
A30: 24 | B30: SAP-QASTesting | C30: CtrlS → AWS | D30: EC2 - Non-Prod (SAP) | E30: Hyderabad | F30: r6a.4xlarge | G30: 550.83 | H30: =G30*12 -> 6609.96 | I30: In Scope | J30: SAP ECC QA (was HANA)
A31: DR — MUMBAI (PDF Validated)
A32: 25 | B32: RAINDC03 DR | C32: CtrlS → AWS DR | D32: EC2 - DR | E32: Mumbai | F32: m6i.xlarge | G32: 226.67 | H32: =G32*12 -> 2720.04 | I32: In Scope | J32: AD DC DR
A33: 26 | B33: Rchbbserver DR | C33: CtrlS → AWS DR | D33: EC2 - DR | E33: Mumbai | F33: m6a.2xlarge | G33: 1114.8 | H33: =G33*12 -> 13377.6 | I33: In Scope | J33: Blood Bank DR
A34: 27 | B34: RCHAEON DR | C34: CtrlS → AWS DR | D34: EC2 - DR | E34: Mumbai | F34: r6a.2xlarge | G34: 1221.95 | H34: =G34*12 -> 14663.4 | I34: In Scope | J34: Biometric DR
A35: 28 | B35: Rainbow_MRD DR | C35: CtrlS → AWS DR | D35: EC2 - DR | E35: Mumbai | F35: c6a.8xlarge | G35: 3319.81 | H35: =G35*12 -> 39837.72 | I35: In Scope | J35: MRD DR
A36: 29 | B36: SAP_PI_PRD DR | C36: CtrlS → AWS DR | D36: EC2 - DR (SAP) | E36: Mumbai | F36: m6a.2xlarge | G36: 477.84 | H36: =G36*12 -> 5734.08 | I36: In Scope | J36: SAP PI DR
A37: 30 | B37: repsapGRP DR | C37: CtrlS → AWS DR | D37: EC2 - DR (SAP) | E37: Mumbai | F37: r6a.2xlarge | G37: 780.14 | H37: =G37*12 -> 9361.68 | I37: In Scope | J37: SAP ECC DR A
A38: 31 | B38: repsapAPP DR | C38: CtrlS → AWS DR | D38: EC2 - DR (SAP) | E38: Mumbai | F38: r6a.2xlarge | G38: 609.84 | H38: =G38*12 -> 7318.08 | I38: In Scope | J38: SAP ECC DR B
A39: 32 | B39: RCHSOLMAN72 DR | C39: CtrlS → AWS DR | D39: EC2 - DR (SAP) | E39: Mumbai | F39: r6a.xlarge | G39: 320.76 | H39: =G39*12 -> 3849.12 | I39: In Scope | J39: SolMan DR
A40: 33 | B40: RAINBOW80992 DR | C40: CtrlS → AWS DR | D40: EC2 - DR | E40: Mumbai | F40: m6a.large | G40: 119.46 | H40: =G40*12 -> 1433.52 | I40: In Scope | J40: IVF DR
A41: 34 | B41: mobileapp DR | C41: CtrlS → AWS DR | D41: EC2 - DR | E41: Mumbai | F41: m6a.2xlarge | G41: 450.48 | H41: =G41*12 -> 5405.76 | I41: In Scope | J41: Mobile DR
A42: EXISTING AWS HMS (Phase 2)
...

Sheet Consolidated Summary
A1: Rainbow Hospitals – Final Consolidated TCO (30-Apr-2026 — v1.3, PDF-validated)
B3: Primary: Hyderabad | DR: Mumbai Active-Passive | Phase 2: HMS to HYD
B5: Category | C5: Monthly (USD) | D5: Annual (USD) | E5: Notes
B6: Primary - Production Servers (CSP 3yr) | C6: ='Primary TCO - Hyderabad'!Q30 -> 10962.73 | D6: =C6*12 -> 131552.76 | E6: CSP 3yr No Upfront ~50% discount.
B7: Primary - Non-Prod Servers (OD best) | C7: ='Primary TCO - Hyderabad'!Q31 -> 1387.59 | D7: =C7*12 -> 16651.08 | E7: Cheaper of 75% util or 8hr/day.
B8: DR - Mumbai (Active-Passive) | C8: ='DR TCO - Mumbai'!O14 -> 8281.29 | D8: =C8*12 -> 99375.48 | E8: 10 critical servers pilot-light.
B9: Supporting Services (HYD + Mumbai) | C9: =SuppServices4ExistingHIS!F29 -> 3948.48 | D9: =C9*12 -> 47381.76 | E9: Inspector, Backup, Config, WAF, DRS.
B10: Marketplace Offerings (Palo Alto + MongoDB) | C10: ='Marketplace Offerings'!F17 -> 5173.08 | D10: =C10*12 -> 62076.96 | E10: Palo Alto PAYG 365-day + MongoDB Atlas. No BYOL.
B11: Existing AWS HMS (Phase 2) | C11: ='Existing AWS HMS (Phase 2)'!G33 -> 6209.14 | D11: =C11*12 -> 74509.68 | E11: Moving Mumbai → HYD + DR Mumbai.
B13: GRAND TOTAL (Complete Rainbow AWS Landscape) | C13: =SUM(C6:C11) -> 35962.31 | D13: =C13*12 -> 431547.72 | E13: Phase 1 + Phase 2 + DR + Marketplace + AD/PACS
C14: =C13-C10 -> 30789.23 | D14: =C14*12 -> 369470.76 | E14: Excluding Marketplace offerings | F14: 369540.94 | G14: =F13-D13 -> -431547.72 | H14: =G13/12 -> 0
C15: =C13-C11 -> 29753.17 | D15: =C15*12 -> 357038.04 | E15: Excluding Phase 2 (Existing AWS HMS)
B16: 🔴 HYD Availability Corrections Applied
B17: CtrlS Primary: RNBWHYDFDBK, RainbowC52431, BIUAT-MIS, Manage_Engine
B18: → T3a replaced with T3 (Windows) or T3 (Linux/Intel - cheaper)
B19: Existing HMS: DEPLOYSERV01, newserver-26-08-2025, New-server-replica
B20: → T3a replaced with T3 (Windows) or T3 (Linux)
B21: Net impact: ~+$45/mo (T3 replacements) - ~$25/mo (T3 savings on Linux) = minimal
B23: 📊 Comparison with Previous TCO
B24: TCO 24-Apr (PDF): $30,794.86/mo | $369,540.94/yr (AWS Pricing Calculator)
B25: TCO 25-Apr: See Grand Total above (includes AD/PACS + Marketplace)
B26: 📋 Next Steps
B27: 1. Share Active-Active quote (Chari requested) — see dedicated sheet
B28: 2. Follow up with Chari for CPU/RAM utilisation data
... B36: 11. AD & PACS: Confirm PACS imaging storage volume for FSx sizing

Sheet Primary TCO - Hyderabad
A1: Primary Region: Hyderabad (ap-south-2) — ControlS Migration | HYD Availability Validated
A2: S.No | B2: Server Name | C2: Scope | D2: SAP? | E2: Group | F2: OS | G2: Processor | H2: Instance | I2: vCPU | J2: RAM (GB) | K2: Pricing | L2: EBS (GB) | M2: EBS Type | N2: Disk Util % | O2: EC2 $/mo | P2: EBS $/mo | Q2: Total $/mo | R2: Sizing Justification
A3: 1 | B3: RAINDC03 | C3: In Scope | D3: No | E3: Production | F3: Windows Server 2019 | G3: Intel | H3: m6i.xlarge | I3: 4 | J3: 16 | K3: CSP 3yr No Upfront | L3: 200 | M3: gp3 | N3: No data provided | O3: 208.43 | P3: 18.24 | Q3: =O3+P3 -> 226.67 | R3: AD Primary DC. Intel M6i (4 vCPU / 16 GB) matches source allocation.
A4: 2 | B4: RAINDC02 | C4: In Scope | D4: No | E4: Production | F4: Windows Server 2019 | G4: Intel | H4: m6i.xlarge | I4: 4 | J4: 16 | K4: CSP 3yr No Upfront | L4: 200 | M4: gp3 | N4: No data provided | O4: 208.43 | P4: 18.24 | Q4: =O4+P4 -> 226.67 | R4: AD Secondary DC. Placed in different AZ for high availability.
A5: 3 | B5: RCHECCDEC | C5: In Scope | D5: YES | E5: Non-Prod | F5: Windows 2012 R2→2019 | G5: AMD | H5: m6a.xlarge | I5: 4 | J5: 16 | K5: OD 8hr/day | L5: 2250 | M5: gp3 | N5: Disk: 85.71% | O5: 139.53 | P5: 0 | Q5: =O5+P5 -> 139.53 | R5: SAP ECC Quality/Dev. AMD M6a certified for SAP NetWeaver. EBS increased to 2250 GB for disk headroom.
A6: 4 | B6: HISPRODDB01_new | C6: OUT OF SCOPE | D6: No | E6: Legacy | F6: Windows 2012 R2 | G6: - | H6: - | I6: - | J6: - | K6: - | L6: - | M6: - | N6: Disk: 88.67% | O6: - | P6: - | Q6: - | R6: Legacy HIS DB — confirmed for decommission. Not migrated to AWS.
A7: 5 | B7: WIN-AKB5JTJTA8S | C7: OUT OF SCOPE | D7: No | E7: Legacy | F7: Windows 2012 R2 | G7: - | H7: - | I7: - | J7: - | K7: - | L7: - | M7: - | N7: No data provided | O7: - | P7: - | Q7: - | R7: Legacy HIS SQL Server — not migrated. Decommission on-prem.
A8: 6 | B8: HISPRODAPP02 | C8: OUT OF SCOPE | D8: No | E8: Legacy | F8: Windows 2012 R2 | G8: - | H8: - | I8: - | J8: - | K8: - | L8: - | M8: - | N8: Disk: 99.82% | O8: - | P8: - | Q8: - | R8: Legacy HIS App Server — not migrated. Disk at critical capacity.
A9: 7 | B9: Rchbbserver (Blood Bank) | C9: In Scope | D9: No | E9: Production | F9: Windows Server 2019 | G9: AMD | H9: m6a.4xlarge | I9: 16 | J9: 64 | K9: CSP 3yr No Upfront | L9: 700 | M9: gp3 | N9: No data provided | O9: 2101.93 | P9: 63.84 | Q9: =O9+P9 -> 2165.77 | R9: Blood Bank + SQL Server Standard. AMD M6a.4xlarge (16 vCPU / 64 GB). Windows SQL required. io2 EBS for ACID compliance.
A10: 8 | B10: Rainbow_MRD_64703_NEW | C10: In Scope | D10: No | E10: Production | F10: Ubuntu Pro 22.04 | G10: AMD | H10: c6a.8xlarge | I10: 32 | J10: 64 | K10: CSP 3yr No Upfront | L10: 21500 | M10: gp3 | N10: Disk: 85.13% | O10: 310.11 | P10: 1960.8 | Q10: =O10+P10 -> 2270.91 | R10: MRD OCR compute-intensive. AMD C6a.8xlarge (32 vCPU / 64 GB). Recommend S3 Intelligent-Tiering for cold archive data.
A11: 9 | B11: RNBWHYDFDBK | C11: In Scope | D11: No | E11: Non-Prod | F11: Windows Server 2022 | G11: Intel | H11: t3.medium | I11: 2 | J11: 4 | K11: OD 8hr/day | L11: 300 | M11: gp3 | N11: No data provided | O11: 24.41 | P11: 0 | Q11: =O11+P11 -> 24.41 | R11: Legacy Feedback application. Non-production burstable workload.
A12: 10 | B12: RainbowC52431 | C12: In Scope | D12: No | E12: Non-Prod | F12: Ubuntu Pro 22.04 | G12: Intel | H12: t3.xlarge | I12: 4 | J12: 16 | K12: OD 8hr/day | L12: 205 | M12: gp3 | N12: No data provided | O12: 28.68 | P12: 22.8 | Q12: =O12+P12 -> 51.48 | R12: ICU monitoring. Non-production burstable. Ubuntu 16.04 EOL — upgrade to 22.04 during migration.
A13: 11 | B13: RCHAEON (Biometric) | C13: In Scope | D13: No | E13: Production | F13: Windows Server 2019 | G13: AMD | H13: r6a.4xlarge | I13: 16 | J13: 128 | K13: CSP 3yr No Upfront | L13: 1100 | M13: gp3 | N13: No data provided | O13: 2157.76 | P13: 100.32 | Q13: =O13+P13 -> 2258.08 | R13: Biometric + SQL Server Standard. AMD R6a.4xlarge (16 vCPU / 128 GB). io2 EBS for transactional consistency.
A14: 12 | B14: RainbowRPA | C14: In Scope | D14: No | E14: Production | F14: Windows Server 2019 | G14: AMD | H14: m6a.2xlarge | I14: 8 | J14: 32 | K14: CSP 3yr No Upfront | L14: 350 | M14: gp3 | N14: No data provided | O14: 345.6 | P14: 36.48 | Q14: =O14+P14 -> 382.08 | R14: RPA and Reporting server. AMD M6a.2xlarge (8 vCPU / 32 GB) general-purpose.
A15: 13 | B15: SAP_PI_PRD_New | C15: In Scope | D15: YES | E15: Production | F15: Windows Server 2019 | G15: AMD | H15: m6a.4xlarge | I15: 16 | J15: 64 | K15: CSP 3yr No Upfront | L15: 1400 | M15: gp3 | N15: Disk: 90.09% | O15: 702.43 | P15: 127.68 | Q15: =O15+P15 -> 830.11 | R15: SAP PI/PO Production. AMD M6a.4xlarge certified for SAP NetWeaver. EBS 1400 GB (headroom from 90% disk util).
A16: 14 | B16: SAP_PI_DEV_New | C16: In Scope | D16: YES | E16: Non-Prod | F16: Windows Server 2019 | G16: AMD | H16: m6a.xlarge | I16: 4 | J16: 16 | K16: OD 8hr/day | L16: 900 | M16: gp3 | N16: Disk: 81.59% | O16: 16.82 | P16: 82.08 | Q16: =O16+P16 -> 98.9 | R16: SAP PI/PO Development. AMD M6a certified for SAP NetWeaver non-production.
A17: 15 | B17: repsapGRP (SAPPRDclusA) | C17: In Scope | D17: YES | E17: Production | F17: Windows Server 2022 | G17: AMD | H17: r6a.2xlarge | I17: 8 | J17: 64 | K17: CSP 3yr No Upfront | L17: 2400 | M17: gp3 | N17: No data provided | O17: 379.13 | P17: 218.88 | Q17: =O17+P17 -> 598.01 | R17: SAP ECC Production (was HANA — now out of scope). AMD R6a.2xlarge (8/64). EBS io2→gp3. SAP NetWeaver certified on AMD.
A18: 16 | B18: repsapAPP (SAPPRDclusB) | C18: In Scope | D18: YES | E18: Production | F18: Windows Server 2022 | G18: AMD | H18: r6a.2xlarge | I18: 8 | J18: 64 | K18: CSP 3yr No Upfront | L18: 1100 | M18: gp3 | N18: No data provided | O18: 379.13 | P18: 100.32 | Q18: =O18+P18 -> 479.45 | R18: SAP ECC Production Node B. AMD R6a.2xlarge (8/64). EBS io2→gp3. SAP NetWeaver certified on AMD.
A19: 17 | B19: RCHSOLMAN72 | C19: In Scope | D19: YES | E19: Production | F19: Windows Server 2019 | G19: AMD | H19: r6a.2xlarge | I19: 8 | J19: 64 | K19: CSP 3yr No Upfront | L19: 1450 | M19: gp3 | N19: Disk: 86.54% | O19: 377.03 | P19: 132.24 | Q19: =O19+P19 -> 509.27 | R19: SAP Solution Manager 7.2. AMD R6a.2xlarge (8/64). HANA no longer required — SolMan on AnyDB. SAP NetWeaver certified on AMD.
A20: 18 | B20: sapgst | C20: In Scope | D20: YES | E20: Non-Prod | F20: Windows 2012→2019 | G20: AMD | H20: m6a.xlarge | I20: 4 | J20: 16 | K20: OD 8hr/day | L20: 730 | M20: gp3 | N20: Disk: 84.76% | O20: 16.26 | P20: 77.52 | Q20: =O20+P20 -> 93.78 | R20: SAP GST Development Sandbox. AMD M6a certified for SAP NetWeaver. Windows Server 2012 EOL — upgrade during migration.
... A29: 27 | B29: mobileapp | C29: In Scope | D29: No | E29: Production | F29: Ubuntu Pro 24.04 | G29: AMD | H29: m6a.4xlarge | I29: 16 | J29: 64 | K29: CSP 3yr No Upfront | L29: 1100 | M29: gp3 | N29: Disk: 79.56% | O29: 176.36 | P29: 100.32 | Q29: =O29+P29 -> 276.68 | R29: Mobile App + Rainbow Shield. AMD M6a.4xlarge (16 vCPU / 64 GB). Evaluate Graviton post-migration.
A30: Production Servers Total (CSP 3yr) | Q30: =Q3+Q4+Q9+Q10+Q13+Q14+Q15+Q17+Q18+Q19+Q23+Q24+Q26+Q29 -> 10962.73
A31: Non-Prod Servers Total (OD best option) | Q31: =Q5+Q11+Q12+Q16+Q20+Q21+Q22+Q25+Q27+Q28 -> 1387.59
A32: TOTAL — Primary Region (Hyderabad) | Q32: =Q30+Q31 -> 12350.32

Sheet DR TCO - Mumbai
A1: DR Region: Mumbai (ap-south-1) — Active-Passive Multi-Region DR
A2: S.No | B2: Server Name | C2: SAP? | D2: DR Mode | E2: OS | F2: Processor | G2: Instance | H2: vCPU | I2: RAM (GB) | J2: Pricing | K2: EBS (GB) | L2: EBS Type | M2: EC2 $/mo | N2: EBS $/mo | O2: Total $/mo | P2: DR Justification
A3: 1 | B3: RAINDC03 (DR) | C3: No | D3: Active-Passive | E3: Windows Server 2019 | F3: Intel | G3: m6i.xlarge | H3: 4 | I3: 16 | J3: CSP 3yr No Upfront | K3: 200 | L3: gp3 | M3: 208.43 | N3: 18.24 | O3: =M3+N3 -> 226.67 | P3: AD Domain Controller DR. Pilot-light (m6i.large) for authentication services. AD multi-site replication.
A4: 2 | B4: Rchbbserver (DR) | C4: No | D4: Active-Passive | E4: Windows Server 2019 | F4: AMD | G4: m6a.2xlarge | H4: 8 | I4: 32 | J4: CSP 3yr No Upfront | K4: 700 | L4: gp3 | M4: 1050.96 | N4: 63.84 | O4: =M4+N4 -> 1114.8 | P4: Blood Bank DR. AMD M6a.2xlarge pilot-light (8 vCPU vs 16 vCPU prod). SQL Always-On async replication.
A5: 3 | B5: RCHAEON (DR) | C5: No | D5: Active-Passive | E5: Windows Server 2019 | F5: AMD | G5: r6a.2xlarge | H5: 8 | I5: 64 | J5: CSP 3yr No Upfront | K5: 1100 | L5: gp3 | M5: 1077.85 | N5: 100.32 | O5: =M5+N5 -> 1178.17 | P5: Biometric DR. AMD R6a.2xlarge pilot-light (64 GB vs 128 GB prod). SQL Always-On replication.
A6: 4 | B6: Rainbow_MRD (DR) | C6: No | D6: Active-Passive | E6: Ubuntu Pro 22.04 | F6: AMD | G6: c6a.8xlarge | H6: 32 | I6: 64 | J6: CSP 3yr No Upfront | K6: 21500 | L6: gp3 | M6: 1359.01 | N6: 1960.8 | O6: =M6+N6 -> 3319.81 | P6: MRD DR. AMD C6a.8xlarge full-size replica for 21 TB data replication.
A7: 5 | B7: SAP_PI_PRD (DR) | C7: YES | D7: Active-Passive | E7: Windows Server 2019 | F7: AMD | G7: m6a.2xlarge | H7: 8 | I7: 32 | J7: CSP 3yr No Upfront | K7: 1400 | L7: gp3 | M7: 350.16 | N7: 127.68 | O7: =M7+N7 -> 477.84 | P7: SAP PI/PO DR. AMD M6a.2xlarge pilot-light (8 vCPU vs 16 vCPU prod). Queue replication.
A8: 6 | B8: repsapGRP (DR) | C8: YES | D8: Active-Passive | E8: Windows Server 2022 | F8: AMD | G8: r6a.2xlarge | H8: 8 | I8: 64 | J8: CSP 3yr No Upfront | K8: 2400 | L8: gp3 | M8: 377.05 | N8: 218.88 | O8: =M8+N8 -> 595.93 | P8: SAP ECC DR Node A. AMD R6a.2xlarge. EBS io2→gp3. Async replication to Mumbai.
A9: 7 | B9: repsapAPP (DR) | C9: YES | D9: Active-Passive | E9: Windows Server 2022 | F9: AMD | G9: r6a.2xlarge | H9: 8 | I9: 64 | J9: CSP 3yr No Upfront | K9: 1100 | L9: gp3 | M9: 377.05 | N9: 100.32 | O9: =M9+N9 -> 477.37 | P9: SAP ECC DR Node B. AMD R6a.2xlarge. EBS io2→gp3. Symmetric to Node A.
A10: 8 | B10: RCHSOLMAN72 (DR) | C10: YES | D10: Active-Passive | E10: Windows Server 2019 | F10: AMD | G10: r6a.xlarge | H10: 4 | I10: 32 | J10: CSP 3yr No Upfront | K10: 1450 | L10: gp3 | M10: 188.52 | N10: 132.24 | O10: =M10+N10 -> 320.76 | P10: SAP SolMan DR. AMD R6a.xlarge pilot-light (32 GB vs 64 GB prod). Standby.
A11: 9 | B11: RAINBOW80992 (DR) | C11: No | D11: Active-Passive | E11: Windows Server 2022 | F11: AMD | G11: m6a.large | H11: 2 | I11: 8 | J11: CSP 3yr No Upfront | K11: 350 | L11: gp3 | M11: 87.54 | N11: 31.92 | O11: =M11+N11 -> 119.46 | P11: IVF Clinical DR. AMD M6a.large pilot-light (2 vCPU vs 8 vCPU prod). Scale-up on failover.
A12: 10 | B12: mobileapp (DR) | C12: No | D12: Active-Passive | E12: Ubuntu Pro 24.04 | F12: AMD | G12: m6a.2xlarge | H12: 8 | I12: 32 | J12: CSP 3yr No Upfront | K12: 1100 | L12: gp3 | M12: 350.16 | N12: 100.32 | O12: =M12+N12 -> 450.48 | P12: Mobile App DR. AMD M6a.2xlarge pilot-light. Ubuntu matching primary OS.
A13: ℹ️ Mumbai has full instance catalogue. All instances used here are available. 10 critical servers in pilot-light mode.
A14: TOTAL DR — Mumbai (Active-Passive) | O14: =SUM(O3:O12) -> 8281.29

Sheet SuppServices4ExistingHIS
A1: Supporting Services — Hyderabad (Primary) + Mumbai (DR) | Availability Validated
A2: S.No | B2: Service | C2: Region | D2: Configuration | E2: HYD/Mumbai Avail | F2: Monthly $ | G2: Notes
A3: 1 | B3: Data Transfer (Intra + Inbound) | C3: Hyderabad | D3: 1.5 TB intra-region/mo | E3: ✅ Available | F3: 69 | G3: Within HYD region.
A4: 2 | B4: Data Transfer - Egress | C4: Hyderabad | D4: 2.5 TB out/mo to internet | E4: ✅ Available | F4: 234.25 | G4: Internet-bound traffic.
A5: 3 | B5: VPC + NAT Gateway | C5: Hyderabad | D5: VPN + NAT Gateway (PDF-aligned) | E5: ✅ Available | F5: 329.83 | G5: HA NAT. VPN to customer DC.
A6: 4 | B6: AWS Inspector | C6: Hyderabad | D6: Vulnerability scanning 24 EC2 instances | E6: ✅ Available | F6: 36.24 | G6: Replaces EDR. Native AWS.
A7: 5 | B7: GuardDuty | C7: Hyderabad | D7: Flow logs + EBS scan + CloudTrail | E7: ✅ Available | F7: 244.6 | G7: Threat detection.
A8: 6 | B8: AWS Config | C8: Hyderabad | D8: Continuous config monitoring | E8: ✅ Available | F8: 18.5 | G8: Compliance + audit.
A9: 7 | B9: AWS Security Hub | C9: Hyderabad | D9: CSPM + findings aggregation | E9: ✅ Available | F9: 85.01 | G9: Central security dashboard.
A10: 8 | B10: CloudTrail | C10: Hyderabad | D10: Management + data events | E10: ✅ Available | F10: 0.2 | G10: Audit logging.
A11: 9 | B11: WAF | C11: Hyderabad | D11: 1 Web ACL + 5 rules | E11: ✅ Available | F11: 12.2 | G11: IVF + Mobile App + HIS UAT.
A12: 10 | B12: CloudWatch | C12: Hyderabad | D12: 150 metrics + 40GB logs | E12: ✅ Available | F12: 84.28 | G12: Monitoring.
A13: 11 | B13: AWS Backup | C13: Hyderabad | D13: 5 TB, 365-day retention | E13: ✅ Available | F13: 391.78 | G13: Replaces CommVault.
A14: 12 | B14: ELB (3x ALB) | C14: Hyderabad | D14: 3 Application Load Balancers | E14: ✅ Available | F14: 74.24 | G14: Public-facing apps.
... A28: 26 | B28: GuardDuty (DR) | C28: Mumbai | D28: DR threat detection | E28: ✅ Available | F28: 98.3 | G28: DR security.
A29: TOTAL Supporting Services | F29: =SUM(F3:F28) -> 3948.48

Sheet Supporting Services
A1: Supporting Services — Hyderabad (Primary) + Mumbai (DR) | Availability Validated
A2: S.No | B2: Service | C2: Region | D2: Configuration | E2: HYD/Mumbai Avail | F2: Monthly $ | G2: Notes
A3: 1 | B3: Data Transfer (Intra + Inbound) | C3: Hyderabad | D3: 1.5 TB intra-region/mo | E3: ✅ Available | F3: 69 | G3: Within HYD region.
A4: 2 | B4: Data Transfer - Egress | C4: Hyderabad | D4: 2.5 TB out/mo to internet | E4: ✅ Available | F4: 234.25 | G4: Internet-bound traffic.
A5: 3 | B5: VPC + NAT Gateway | C5: Hyderabad | D5: NAT GW in 2 AZs + S2S VPN | E5: ✅ Available | F5: 271.14 | G5: HA NAT. VPN to customer DC.
A6: 4 | B6: AWS Inspector | C6: Hyderabad | D6: Vulnerability scanning 24 EC2 instances | E6: ✅ Available | F6: 36.24 | G6: Replaces EDR. Native AWS.
A7: 5 | B7: GuardDuty | C7: Hyderabad | D7: Flow logs + EBS scan + CloudTrail | E7: ✅ Available | F7: 244.6 | G7: Threat detection.
A8: 6 | B8: AWS Config | C8: Hyderabad | D8: Continuous config monitoring | E8: ✅ Available | F8: 18.5 | G8: Compliance + audit.
A9: 7 | B9: AWS Security Hub | C9: Hyderabad | D9: CSPM + findings aggregation | E9: ✅ Available | F9: 85 | G9: Central security dashboard.
A10: 8 | B10: CloudTrail | C10: Hyderabad | D10: Management + data events | E10: ✅ Available | F10: 0.2 | G10: Audit logging.
A11: 9 | B11: WAF | C11: Hyderabad | D11: 1 Web ACL + 5 rules | E11: ✅ Available | F11: 12.2 | G11: IVF + Mobile App + HIS UAT.
A12: 10 | B12: CloudWatch | C12: Hyderabad | D12: 150 metrics + 40GB logs | E12: ✅ Available | F12: 84.28 | G12: Monitoring.
A13: 11 | B13: AWS Backup | C13: Hyderabad | D13: 5 TB primary, 365-day warm retention (customer requirement) | E13: ✅ Available | F13: 550 | G13: 365-day retention per customer. Est: 5TB primary + 365 days incremental. ⚠️ Validate in AWS Calculator.
A14: 12 | B14: ELB (3x ALB) | C14: Hyderabad | D14: 3 Application Load Balancers | E14: ✅ Available | F14: 74.24 | G14: Public-facing apps.
... A27: 25 | B27: GuardDuty (DR) | C27: Mumbai | D27: DR threat detection | E27: ✅ Available | F27: 98.3 | G27: DR security.
A28: TOTAL Supporting Services | F28: =SUM(F3:F27) -> 4047.36

Sheet Marketplace Offerings
A1: AWS Marketplace Offerings — Palo Alto + MongoDB (HYD + Mumbai Validated)
A2: S.No | B2: Product | C2: Region | D2: Configuration | E2: Availability | F2: Monthly $ | G2: Notes
A3: 1 | B3: Palo Alto VM-Series (EC2) | C3: Hyderabad | D3: 2x c6i.xlarge HA pair | E3: ✅ Available | F3: 128.86 | G3: VM-Series EC2 compute. 2x c6i.xlarge HA pair. CSP 3yr pricing.
A4: 2 | B4: Palo Alto VM-Series (EBS) | C4: Hyderabad | D4: 2x 100 GB gp3 | E4: ✅ Available | F4: 18.24 | G4: OS + logs storage.
A5: 3 | B5: Gateway Load Balancer | C5: Hyderabad | D5: GWLB for Palo Alto HA | E5: ✅ Available | F5: 24.68 | G5: Traffic routing.
A6: 4 | B6: Palo Alto PAYG 365-day License | C6: Hyderabad | D6: 2x c6i.xlarge — PAYG 365-day (71% savings) | E6: ✅ Marketplace | F6: 724 | G6: PAYG $1.71/hr → 365-day: $0.4959/hr × 730hr = $362/mo × 2 instances. Includes Adv Threat Prevention, URL Filtering, WildFire, DNS Security, GlobalProtect + 24x7 Premium Support. Source: aws.amazon.com/marketplace/pp/prodview-3xtziatyes54i
A7: 5 | B7: Palo Alto DR (EC2) | C7: Mumbai | D7: 2x c6i.xlarge passive standby | E7: ✅ Available | F7: 80.3 | G7: DR pair. Instances stopped until failover. EC2 compute only.
A8: 6 | B8: Palo Alto DR (EBS) | C8: Mumbai | D8: 2x 100 GB gp3 | E8: ✅ Available | F8: 18.24 | G8: DR EBS (provisioned).
A9: 7 | B9: Gateway Load Balancer (DR) | C9: Mumbai | D9: GWLB DR | E9: ✅ Available | F9: 24.68 | G9: Standby GWLB.
A10: 8 | B10: Palo Alto PAYG 365-day (DR) | C10: Mumbai | D10: 2x c6i.xlarge — PAYG 365-day (DR pair) | E10: ✅ Marketplace | F10: 724 | G10: DR pair: Same 365-day rate. License commits to annual contract regardless of instance state. Same security subs included.
A11: 9 | B11: MongoDB Atlas HMIS Cluster 1 | C11: Hyderabad (Atlas) | D11: M40 - 16 GB / 750 GB | E11: ✅ Since Mar 2025 | F11: 800.02 | G11: Primary HMS MongoDB cluster. Marketplace.
A12: 10 | B12: MongoDB Atlas HMIS Cluster 2 | C12: Hyderabad (Atlas) | D12: M50 - 32 GB / 1,596 GB | E12: ✅ Since Mar 2025 | F12: 1200.02 | G12: Secondary HMS. Marketplace.
A13: 11 | B13: MongoDB Atlas App/SAP Cluster | C13: Hyderabad (Atlas) | D13: M30 - 8 GB / 200 GB | E13: ✅ Since Mar 2025 | F13: 450.02 | G13: SAP-Atlas dependency.
A14: 12 | B14: MongoDB Atlas Multi-Region DR | C14: Mumbai (Atlas) | D14: Cross-region replica premium | E14: ✅ Available | F14: 980.02 | G14: 30-40% premium. Auto failover.
... A16: 14 | B16: HMS Vendor BOQ (placeholder) | C16: Hyderabad | D16: IQVIA/Care Expert/MyHealthcare | E16: Pending | F16: 0 | G16: Pending Srini/Chari decision.
A17: TOTAL Marketplace Offerings | F17: =SUM(F3:F16) -> 5173.08
B19: 🛒 Marketplace Availability Verification (24-Apr-2026)
B20: • Palo Alto VM-Series: ✅ Available globally via AWS Marketplace (HYD + Mumbai)
B21: • MongoDB Atlas: ✅ Hyderabad since March 2025, Mumbai long-standing
B22: • Both counts toward MAP/PPA qualification via AWS Marketplace spend
B24: ⚠️ Action items:
B25: 1. Palo Alto: 365-day PAYG contract selected — no BYOL. Confirm annual commitment with AWS.
B26: 2. Confirm MongoDB single-region vs multi-region DR with Chari
B27: 3. Latespot CRM details pending Chari
B28: 4. HMS Vendor BOQ pending Srini/Chari decision
B29: https://www.mongodb.com/products/platform/atlas-cloud-providers/aws/pricing
B30: https://www.mongodb.com/docs/atlas/reference/amazon-aws/#std-label-amazon-aws
B31: https://aws.amazon.com/marketplace/pp/prodview-3xtziatyes54i?sr=0-2&ref_=beagle&applicationId=AWSMPContessa
B33: Requirements from Customer - 24th april 2026 (Minfy send email)
B34: PACS Infra details with Active Directory details | D34: SAP Rise - Internal Check (Infra - Gopal, Functional - AWS)
B35: CRM - SaaS details
B36: HMS Vendor BOQ post discussion with vendor
B37: Palo Alto License
B38: HMS ARM Based architecture
B39: Static page hosting with S3 + Cloudfront
B40: CPU / RAM Utilization
B41: Application Depedency (Server Depedent)
E50: https://www.mongodb.com/pricing/calculator/estimate/69eca2abcf761e821c9acfed/cluster-configuration/69eca36bcf761e821c9acff7?name=Cluster+4&isAdvancedConfigExpanded=false&isBackupNetworkExpanded=false&isPrimaryConfigExpanded=true&region=AP_SOUTH_1&diskSizeGb=100

Sheet HIS BOM - KareXpert
A1: KareXpert — AWS BOM Detail | 2,500 Beds | Primary: Hyderabad (EKS/Kubernetes)
A2: Containerised microservices on EKS (Kubernetes). 24 Graviton worker nodes. All Linux — available in ap-south-2.
A4: # | B4: Component | C4: Instance/Config | D4: Qty | E4: vCPU | F4: RAM (GB) | G4: EC2 OD $/mo ea | H4: EC2 CSP 3yr ea | I4: Total $/mo | J4: Notes
A5: 1 | B5: EKS Cluster Control Plane | C5: EKS Standard | D5: 1 | E5: - | F5: - | G5: 73 | H5: 73 | I5: =H5*D5 -> 73 | J5: Managed K8s control plane. $0.10/hr = $73/mo fixed.
A6: 2 | B6: EKS Workers — Core Apps | C6: r6g.xlarge | D6: 18 | E6: 4 | F6: 32 | G6: 134.32 | H6: 58.18 | I6: =H6*D6 -> 1047.24 | J6: Core application + low-profile microservices. 100 GB EBS each.
A7: 3 | B7: EKS Workers — High-Profile | C7: r6g.2xlarge | D7: 6 | E7: 8 | F7: 64 | G7: 268.64 | H7: 116.35 | I7: =H7*D7 -> 698.1 | J7: Heavy microservices (billing, EMR, analytics). 200 GB EBS each.
A8: 4 | B8: EBS for PVCs | C8: gp3 3 TB | D8: 1 | E8: - | F8: - | G8: - | H8: 438.26 | I8: =H8*D8 -> 438.26 | J8: Persistent Volume Claims for stateful services.
A9: 5 | B9: Jump Server (Bastion) | C9: t3.medium | D9: 1 | E9: 2 | F9: 4 | G9: 33.87 | H9: 17.66 | I9: =H9*D9 -> 17.66 | J9: Secure SSH access. 20 GB SSD. Took t3.medium as t2.medium is not available in ap-south2
A11: Additional AWS Services (from KareXpert BOM)
A12: # | B12: Service | C12: Description | I12: Est $/mo | J12: Notes
A13: 6 | B13: S3 Object Storage | C13: 10 TB Standard for backups, logs, files | I13: 256 | J13: S3 Standard 10 TB.
A14: 7 | B14: MongoDB Atlas M60 | C14: 3-node replica (16 vCPU/64 GB/1 TB per node) | I14: 1800 | J14: M60 tier via Marketplace. ⚠️ Check if replaces existing Atlas clusters or additional.
A15: 8 | B15: WAF | C15: 3M requests/mo, 3 rules | I15: 12 | J15: Already in shared services — may be $0 incremental.
A16: 9 | B16: ALB | C16: Application Load Balancer | I16: 25 | J16: 1 ALB for EKS ingress.
A17: 10 | B17: Route 53 | C17: DNS | I17: 6 | J17: Already in shared services — may be $0 incremental.
A18: 11 | B18: AWS Certificate Manager | C18: Wildcard SSL | I18: 0 | J18: Free for ACM public certs.
A19: 12 | B19: AWS Inspector | C19: EC2 scanning | I19: 0 | J19: Already in shared Supporting Services.
A20: 13 | B20: AWS ECR | C20: Container image registry | I20: 15 | J20: ~150 GB images × $0.10/GB.
A21: 14 | B21: Security Services | C21: SecurityHub+GuardDuty+KMS+Config+CloudWatch+SES | I21: 0 | J21: ⚠️ OVERLAP — already in shared Supporting Services. $0 incremental.
B23: EKS + EC2 Compute (1 cluster + 24 workers + bastion, CSP 3yr) | I23: 2670.17
B24: Additional AWS Services | I24: 2098
B25: TOTAL KareXpert HIS Monthly Cost | I25: 4768.17
B27: ⚠️ IMPORTANT NOTES
B28: 1. All EC2 rates are ESTIMATES for ap-south-2 Graviton instances. Validate in AWS Pricing Calculator.
B29: 2. MongoDB Atlas M60 ($1,800/mo) — check if this REPLACES existing 3 Atlas clusters ($2,450) or is ADDITIONAL.
B30: If replacement: net saving of $650/mo. If additional: +$1,800/mo.
B31: 3. Security/monitoring services already in shared Supporting Services — $0 incremental.
B32: 4. Total vCPU: 122 = 122 | Total RAM: 964 = 964 GB | 25 instances (1 EKS + 24 workers + 1 bastion)
B33: 5. EKS cluster fee ($73/mo) is NOT covered by Savings Plans — always full price.

Sheet HIS BOM - MyHealthcare
A1: MyHealthcare (MHEA) — AWS BOM Detail | 1,000 CCU | Primary: Hyderabad
A2: Microservices on EC2 VMs (214 Graviton instances). All instances Linux/Graviton — available in ap-south-2.
A4: # | B4: Component | C4: Instance Type | D4: Qty | E4: vCPU | F4: RAM (GB) | G4: EC2 OD $/mo ea | H4: EC2 CSP 3yr ea | I4: Total $/mo | J4: Notes
A5: 1 | B5: Compute Type 1 | C5: c6g.large | D5: 98 | E5: 2 | F5: 4 | G5: 43.51 | H5: 15.99 | I5: =H5*D5 -> 1567.02 | J5: Stateless app microservices. Compute-optimised Graviton.
A6: 2 | B6: Compute Type 2 | C6: m6g.large | D6: 24 | E6: 2 | F6: 8 | G6: 51.76 | H6: 18.76 | I6: =H6*D6 -> 450.24 | J6: General-purpose microservices.
A7: 3 | B7: Compute Type 3 | C7: c6g.xlarge | D7: 48 | E7: 4 | F7: 8 | G7: 87.02 | H7: 31.97 | I7: =H7*D7 -> 1534.56 | J7: Mid-tier compute microservices.
A8: 4 | B8: Compute Type 4 | C8: m6g.xlarge | D8: 36 | E8: 4 | F8: 16 | G8: 103.51 | H8: 37.52 | I8: =H8*D8 -> 1350.72 | J8: Memory-balanced microservices.
A9: 5 | B9: Compute Type 5 | C9: m6g.2xlarge | D9: 8 | E9: 8 | F9: 32 | G9: 207.03 | H9: 75.04 | I9: =H9*D9 -> 600.32 | J9: Heavy workload services (reports, analytics).
A11: Additional AWS Services (from MyHealthcare BOM)
A12: # | B12: Service | C12: Description | I12: Est $/mo | J12: Notes
A13: 6 | B13: S3 Storage | C13: Standard 20GB + Glacier Deep Archive 20GB | I13: 5 | J13: Minimal storage — app data.
A14: 7 | B14: CloudFront | C14: CDN for patient-facing app | I14: 50 | J14: Estimate based on 500 GB/mo transfer.
A15: 8 | B15: API Gateway | C15: REST API management | I15: 35 | J15: Estimate based on 10M requests/mo.
A16: 9 | B16: CloudWatch | C16: Monitoring for 214 instances | I16: 150 | J16: Already in shared services — may overlap.
A17: 10 | B17: Cognito | C17: User authentication (1000 CCU) | I17: 275 | J17: 1000 MAU × $0.0055 + 50K auth events.
A18: 11 | B18: Lambda | C18: Serverless functions | I18: 20 | J18: Event-driven processing.
A19: 12 | B19: SES | C19: Email notifications | I19: 10 | J19: Transactional emails.
A20: 13 | B20: SNS | C20: Push notifications | I20: 5 | J20: Mobile push + SMS.
A21: 14 | B21: ALB | C21: Application Load Balancer | I21: 25 | J21: 1 ALB for HIS traffic. ⚠️ Check if shared ALBs cover this.
A22: 15 | B22: VPC (2 S2S VPN + 5 IPv4) | C22: Network + 5 public IPs | I22: 55 | J22: VPN to branches. 5 EIPs × $3.60 + VPN.
A23: 16 | B23: Network Firewall | C23: AWS Network Firewall | I23: 175 | J23: ⚠️ If Palo Alto covers this, remove.
A24: 17 | B24: Security Services | C24: Detective+Inspector+SecurityLake+SecurityHub+GuardDuty+WAF+Audit+Config+CloudTrail+IAM+KMS | I24: 0 | J24: ⚠️ OVERLAP — already in shared Supporting Services. $0 incremental.
... A26: 19 | B26: Data Transfer | C26: Intra-Region 2 TB/mo | I26: 30 | J26: Within Hyderabad region.
B28: EC2 Compute (214 instances, CSP 3yr) | I28: 7532.62
B29: Additional AWS Services | I29: 850
B30: TOTAL MyHealthcare HIS Monthly Cost | I30: 8382.62
B32: ⚠️ IMPORTANT NOTES
B33: 1. All EC2 rates are ESTIMATES for ap-south-2 Graviton instances. Validate in AWS Pricing Calculator.
B34: 2. Security services (GuardDuty, Inspector, SecurityHub, WAF, Config, CloudTrail, KMS) = $0 incremental
B35: because they are already in the shared Supporting Services sheet.
B36: 3. If Palo Alto covers Network Firewall functionality, remove the $175/mo line.
B37: 4. CloudWatch monitoring may overlap with shared services — validate.
B38: 5. Total vCPU: 644 | Total RAM: 1800 GB | 214 instances

Sheet Active-Active vs Passive
A1: DR Comparison: Active-Passive vs Active-Active (Chari Requested Both)
B3: DR Attribute | C3: Active-Passive (Current Quote) | D3: Active-Active (Optional) | E3: Difference
B4: DR Instance Sizing | C4: Pilot-light (smaller) | D4: Full size (match prod) | E4: +70% compute
B5: RPO (Recovery Point Objective) | C5: < 1 hour | D5: Near-zero
B6: RTO (Recovery Time Objective) | C6: 30-60 minutes | D6: < 5 minutes
B7: Traffic Distribution | C7: Mumbai on failover only | D7: Both regions serve | E7: +100% compute
B8: Replication Mode | C8: Continuous async | D8: Synchronous critical DBs
B9: Monthly DR Cost (EC2 + Supporting) | C9: =C52 -> 10587.5 | D9: =D52 -> 13125.3 | E9: =D9-C9 -> 2537.8
B10: Annual DR Cost (EC2 + Supporting) | C10: =C9*12 -> 127050 | D10: =D9*12 -> 157503.6 | E10: =D10-C10 -> 30453.6
B11: Data Transfer | C11: ~$60/mo | D11: ~$200/mo | E11: +$140/mo
B12: Operational Complexity | C12: Simpler | D12: Complex | E12: Higher overhead
B13: Best Fit For | C13: 30-min RTO tolerance | D13: Zero-downtime critical
B15: Active-Active DR Costing — Full Size Instances (Mumbai)
B17: Server | C17: Instance (Full Size) | D17: EC2 $/mo | E17: EBS $/mo | F17: Total $/mo
B18: RAINDC03 (DR) | C18: m6i.xlarge | D18: 208.43 | E18: 18.24 | F18: =D18+E18 -> 226.67
B19: Rchbbserver (DR) | C19: m6a.4xlarge | D19: 2091.71 | E19: 101.92 | F19: =D19+E19 -> 2193.63
B20: RCHAEON (DR) | C20: r6a.4xlarge | D20: 2141.7 | E20: 160.16 | F20: =D20+E20 -> 2301.86
B21: Rainbow_MRD (DR) | C21: c6a.8xlarge | D21: 1359.01 | E21: 1960.8 | F21: =D21+E21 -> 3319.81
B22: SAP_PI_PRD (DR) | C22: m6a.4xlarge | D22: 702.43 | E22: 127.68 | F22: =D22+E22 -> 830.11
B23: repsapGRP (DR) | C23: r6a.2xlarge | D23: 429.1 | E23: 218.88 | F23: =D23+E23 -> 647.98
B24: repsapAPP (DR) | C24: r6a.2xlarge | D24: 438.65 | E24: 100.32 | F24: =D24+E24 -> 538.97
B25: RCHSOLMAN72 (DR) | C25: r6a.2xlarge | D25: 465.71 | E25: 132.24 | F25: =D25+E25 -> 597.95
B26: RAINBOW80992 (DR) | C26: m6a.2xlarge | D26: 347.42 | E26: 31.92 | F26: =D26+E26 -> 379.34
B27: mobileapp (DR) | C27: m6a.4xlarge | D27: 176.36 | E27: 100.32 | F27: =D27+E27 -> 276.68
B28: TOTAL Active-Active DR (Full Size, CSP 3yr) | F28: =SUM(F18:F27) -> 11313
B30: Active-Active Supporting Services — Mumbai (Full Active Region) | C30: Monthly (USD) | D30: Annual (USD) | E30: Notes
B31: Service | C31: Monthly $ | D31: Notes | E31: Smaller instances, scale-up on failover
B32: Data Transfer Egress (Mumbai) | C32: 303.25 | D32: Active region serving internet traffic — combined intra+inbound+egress matches HYD active-region (PDF: $303.25) | E32: Full production-size, always running
B33: Data Transfer Inter-Region | C33: 176.13 | D33: Bi-directional HYD↔Mumbai — set to AP-validated value as floor; actual AA cost may exceed this | E33: Additional cost for Active-Active
B34: VPC + NAT Gateway (Mumbai) | C34: 329.83 | D34: Full HA NAT for active traffic (PDF-validated HYD: VPN + NAT Gateway $329.83)
B35: AWS Inspector (Mumbai) | C35: 36.24 | D35: Full scanning (PDF price)
B36: GuardDuty (Mumbai) | C36: 244.6 | D36: Full threat detection (PDF price)
B37: AWS Config (Mumbai) | C37: 18.5 | D37: Compliance monitoring
B38: Security Hub (Mumbai) | C38: 85.01 | D38: CSPM for active region (PDF-validated HYD: $85.01)
B39: CloudTrail (Mumbai) | C39: 0.2 | D39: Audit logging
B40: WAF (Mumbai) | C40: 12.2 | D40: Web protection for active traffic
B41: CloudWatch (Mumbai) | C41: 84.28 | D41: Full monitoring (PDF price)
B42: AWS Backup (Mumbai) | C42: 391.78 | D42: Full primary backup (matches HYD per PDF: $391.78). AP Mumbai DR backup is lower at $295.62 because it is CRR copy only.
B43: ELB 3x ALB (Mumbai) | C43: 74.24 | D43: Full load balancing (PDF price)
B44: S3 2TB (Mumbai) | C44: 52.74 | D44: Logs and storage (PDF price)
...

Sheet Existing AWS HMS (Phase 2)
A1: Existing AWS HMS Workloads — Phase 2 Migration to Hyderabad
A2: S.No | B2: Service | C2: Resource | D2: Instance/Config | E2: OS | F2: Region | G2: Est $/mo | H2: Notes
A3: 1 | B3: EC2 | C3: AAHISRPTSERV02-Prod-rep | D3: m6a.2xlarge | E3: Linux | F3: Hyderabad | G3: 104.32 | H3: HMS Report Server 2. m6a.2xlarge Linux CSP 3yr NU. [Source: AWS Calculator ap-south-2, 250GB EBS]
A4: 2 | B4: EC2 | C4: AAINTFACESERV02-Prod | D4: m6a.2xlarge | E4: Linux | F4: Hyderabad | G4: 99.76 | H4: Interface Server 2. m6a.2xlarge Linux CSP 3yr NU. [Source: AWS Calculator ap-south-2, 200GB EBS]
A5: 3 | B5: EC2 | C5: AAHISAPPSERV02-Prod | D5: m6a.2xlarge | E5: Linux | F5: Hyderabad | G5: 99.76 | H5: HMS App Server 2. m6a.2xlarge Linux CSP 3yr NU. [Source: AWS Calculator ap-south-2, 200GB EBS]
A6: 4 | B6: EC2 | C6: AAHISAPPSERV03-Prod | D6: m6a.2xlarge | E6: Linux | F6: Hyderabad | G6: 99.76 | H6: HMS App Server 3. m6a.2xlarge Linux CSP 3yr NU. [Source: AWS Calculator ap-south-2, 200GB EBS]
A7: 5 | B7: EC2 | C7: MIRTHDBSERV01-DR | D7: m6a.large | E7: Linux | F7: Hyderabad | G7: 130.87 | H7: Mirth DR Server. m6a.large Linux CSP 3yr NU. [Source: AWS Calculator ap-south-2, 1TB EBS]
A8: 6 | B8: EC2 | C8: AAINTFACESERV01-Prod | D8: m6a.2xlarge | E8: Linux | F8: Hyderabad | G8: 99.76 | H8: Interface Server 1. m6a.2xlarge Linux CSP 3yr NU. [Source: AWS Calculator ap-south-2, 200GB EBS]
A9: 7 | B9: EC2 | C9: AAHISAPPSERV01-Prod | D9: m6a.2xlarge | E9: Linux | F9: Hyderabad | G9: 99.76 | H9: HMS App Server 1. m6a.2xlarge Linux CSP 3yr NU. [Source: AWS Calculator ap-south-2, 200GB EBS]
A10: 8 | B10: EC2 | C10: AAHISRPTSERV01-Prod-rep | D10: m6a.2xlarge | E10: Linux | F10: Hyderabad | G10: 99.76 | H10: HMS Report Server 1. m6a.2xlarge Linux CSP 3yr NU. [Source: AWS Calculator ap-south-2, 200GB EBS]
A11: 9 | B11: EC2 | C11: MIRTHDBSERV01-Prod-1 | D11: m6a.2xlarge | E11: Linux | F11: Hyderabad | G11: 192.01 | H11: Mirth Primary - CRITICAL HL7 broker. m6a.2xlarge Linux CSP 3yr NU. [Source: AWS Calculator ap-south-2, 1TB EBS]
A12: 10 | B12: EC2 | C12: DEPLOYSERV01 | D12: t3.small (fixed) | E12: Linux | F12: Hyderabad | G12: 10.87 | H12: DEPLOYSERV01 t3.small OD 8hr/day, 180 GB. [Source: AWS Calculator 30-Apr-2026]
A13: 11 | B13: EC2 | C13: Grafana Monitoring | D13: c6a.large | E13: Linux | F13: Hyderabad | G13: 63.32 | H13: Grafana c6a.large CSP 3yr No Upfront, 500 GB. [Source: AWS Calculator 30-Apr-2026]
A14: 12 | B14: EC2 | C14: newserver-26-08-2025 | D14: t3.xlarge (fixed) | E14: Windows | F14: Hyderabad | G14: 58.66 | H14: Unknown server — confirm purpose with Chari. t3.xlarge Win OD 8hr/day. [Estimated: needs validation]
... A30: 28 | B30: GuardDuty | C30: DR Threat Detection | D30: Various | E30: - | F30: Mumbai | G30: 224.4 | H30: GuardDuty DR Threat Detection. [Source: AWS Calculator ap-south-1]
A31: 29 | B31: CloudWatch | C31: DR Monitoring | D31: 100 metrics | E31: - | F31: =SUM(F3:F30) -> 0 | G31: 64.48 | H31: CloudWatch DR 100 metrics. [Source: AWS Calculator ap-south-1]
A32: 30 | B32: AWS Backup | C32: Cross-Region Copy | D32: 3.5 TB | E32: - | F32: Mumbai | G32: 312.7 | H32: AWS Backup Cross-Region Copy 3.5TB. [Source: AWS Calculator ap-south-1]
A33: TOTAL Existing AWS HMS | G33: =SUM(G3:G32) -> 6209.14
B35: *Pricing yet to validate. Required Details Bill of AWS, will help here.

Sheet AD & PACS Infrastructure
A1: Active Directory & PACS Infrastructure — Rainbow Hospitals
A2: Updated: 25-Apr-2026 | AD details from Narsima (AWS SA) | PACS: Separate Managed AD domain
A4: ARCHITECTURE: Dual AD — Self-managed (core) + AWS Managed AD (PACS)
A41: KEY ARCHITECTURE DECISIONS
A42: 1. RAINDC03/02 (rainbow.local) stays in Primary TCO — serves HIS, SAP, Blood Bank, Biometric, all existing workloads. No changes.
A43: 2. New AWS Managed Microsoft AD (imaging.rainbow.local) created specifically for PACS — separate security boundary.
A44: 3. One-way forest trust: PACS domain trusts Rainbow domain → radiologists get SSO to PACS without separate login.
A45: 4. PACS ↔ HIS integration via HL7/Mirth Connect is network-level (TCP/IP) — not AD-dependent.
A46: 5. 25 branch AD servers stay on-premises — provide local auth, DNS, DHCP. Not migrated to AWS.
A47: 6. Amazon FSx (rainbow.local) replaces 12 TB branch file shares — domain-joined to RAINDC03/02.
A48: 7. FSx (imaging.rainbow.local) for PACS imaging storage — domain-joined to Managed AD.
A49: 8. Route 53 Resolver still required — forwards DNS for both domains + CtrlS trust.
... A52: AD ENVIRONMENT SUMMARY (From Narsima — 25-Apr-2026)
A53: Total AD Objects | B53: 3,374 (users + computers)
A54: Domain Structure | B54: Single domain (rainbow.local)
A55: Group Policy | B55: GPO policies in place, not complex
A56: DNS/DHCP | B56: Core switch at most locations; 4 locations have DNS on local AD server
A57: AD-Dependent Apps | B57: LDAP configured for HIS (Hospital Information System)
A58: Trust Relationships | B58: Existing trust with CtrlS domain
A59: Branch Connectivity | B59: MPLS to CtrlS, AWS VPN tunnels already configured
A60: File Share Storage | B60: 20 TB total, 12 TB used (breakdown per location pending)
A61: OS Upgrades Needed | B61: 13 servers on Win 2016, 1 on Win 2012 R2 (EOL), 1 Eval license
A63: BRANCH AD SERVER INVENTORY (25 Locations — On-Premises, NOT migrated to AWS)
A64: S.No | B64: Location | C64: IP Address | D64: Hostname | E64: OS | F64: Migration Strategy | G64: DNS on Local Server? | H64: Notes
A65: 1 | B65: Secunderabad | C65: 192.168.40.12 | D65: RCHVKPSV03 | E65: Win Server 2019 Std | F65: Keep On-Prem | G65: No | H65: Current OS
A66: 2 | B66: Kondapur OP | C66: 192.168.30.12 | D66: RCHMPSV01 | E66: Win Server 2016 Std | F66: Keep On-Prem | G66: No | H66: Upgrade 2016→2022
A67: 3 | B67: Kondapur IP | C67: 192.168.3.10 | D67: RCHKPSV04 | E67: Win Server 2016 Std | F67: Keep On-Prem | G67: No | H67: Upgrade 2016→2022
A68: 4 | B68: Malviya Nagar | C68: 192.168.13.25 | D68: RCHMNSV001 | E68: Win Server 2012 R2 Std | F68: Keep On-Prem | G68: No | H68: ⚠️ EOL — upgrade mandatory
A69: 5 | B69: Rosewalk | C69: 192.168.34.12 | D69: RCHPPDSV01 | E69: Win Server 2016 | F69: Keep On-Prem | G69: No | H69: Upgrade 2016→2022
A70: 6 | B70: Vizag Health City | C70: 192.168.36.12 | D70: RCHHCVSV01 | E70: Win Server 2019 | F70: Keep On-Prem | G70: Yes | H70: DNS on local AD
A71: 7 | B71: Guindy | C71: 192.168.25.21 | D71: RCHGDYSV01 | E71: Win Server 2016 | F71: Keep On-Prem | G71: No | H71: Upgrade 2016→2022
A72: 8 | B72: Hebbal | C72: 192.168.37.13 | D72: RCHHBBSV01 | E72: Win Server 2019 | F72: Keep On-Prem | G72: No | H72: Current OS
A73: 9 | B73: Heart Institute | C73: 192.168.32.12 | D73: RCHBCHSV001 | E73: Win Server 2016 | F73: Keep On-Prem | G73: Yes | H73: DNS on local AD
A74: 10 | B74: BG Road | C74: 192.168.8.12 | D74: RCHBGSV05 | E74: Win Server 2016 Std | F74: Keep On-Prem | G74: No | H74: Upgrade 2016→2022
A75: 11 | B75: Hydernagar | C75: 192.168.6.10 | D75: RCHHNSV03 | E75: Win Server 2016 Std | F75: Keep On-Prem | G75: No | H75: Upgrade 2016→2022
A76: 12 | B76: Currency Nagar | C76: 192.168.5.12 | D76: RCHCUVSV01 | E76: Win Storage Server 2016 | F76: Keep On-Prem | G76: No | H76: ⚠️ Storage Server — file share priority
... A88: 24 | B88: Hennur Clinic | C88: 192.168.70.9 | D88: RCHHNCSV01 | E88: Win Server 2022 Std | F88: Keep On-Prem | G88: No | H88: Latest OS
A90: AWS SERVICES — AD & PACS INFRASTRUCTURE (Added to TCO)
A91: S.No | B91: Service | C91: Region | D91: Configuration | E91: Hosting Env | F91: Monthly $ (USD) | G91: Annual $ (USD) | H91: Notes
A92: 1 | B92: AWS Managed AD (PACS) | C92: Hyderabad | D92: Standard — imaging.rainbow.local | E92: AD Infrastructure | F92: 134 | G92: =F92*12 -> 1608 | H92: Separate AD for PACS. 2 DCs auto-managed in 2 AZs.
...

Sheet Draft
B4: Server | C4: Source (GB) | D4: Disk Util % | E4: Used (GB) | F4: New EBS (GB) | G4: Rationale
B5: SAP_PI_PRD_New | C5: 1150 | D5: 0.9009 | E5: ~1,036 | F5: 1400 | G5: Highest active util. 1036/0.70 = 1,480 → rounded to 1,400
B6: RCHSOLMAN72 | C6: 1250 | D6: 0.8654 | E6: ~1,082 | F6: 1450 | G6: 1082/0.70 = 1,546 → rounded to 1,450
B7: RCHECCDEC | C7: 1946 | D7: 0.8571 | E7: ~1,668 | F7: 2250 | G7: 1668/0.70 = 2,383 → rounded to 2,250
B8: sapgst | C8: 730 | D8: 0.8476 | E8: ~619 | F8: 850 | G8: 619/0.70 = 884 → rounded to 850
B9: SAP_PI_DEV_New | C9: 800 | D9: 0.8159 | E9: ~653 | F9: 900 | G9: Just above 80%, small buffer added
B10: SAP-DevTesting | C10: 1100 | D10: 0.8074 | E10: ~888 | F10: 1200 | G10: At 80% threshold, small buffer
